Workbook

Sheet TOTAL VOLUME
A1: Wgt | B1: 2Day*2 | C1: 2Day*3 | D1: 2Day*4 | E1: 2Day*5 | F1: 2Day*6 | G1: 2Day*7 | H1: 2Day*8 | I1: 3Day*2 | J1: 3Day*3 | K1: 3Day*4 | L1: 3Day*5 | M1: 3Day*6 | N1: 3Day*7 | O1: 3Day*8 | P1: Ground*2 | Q1: Ground*3 | R1: Ground*4 | S1: Ground*5 | T1: Ground*6 | U1: Ground*7 | V1: Ground*8 | W1: Next Day AM*2 | X1: Next Day AM*3 | Y1: Next Day AM*4 | Z1: Next Day AM*5 | AA1: Next Day AM*6 | AB1: Next Day AM*7 | AC1: Next Day AM*8
A2: 1 | B2: 57 | C2: 18 | D2: 39 | E2: 39 | F2: 29 | G2: 9 | H2: 34 | I2: 9 | J2: 1 | K2: 5 | L2: 7 | M2: 6 | N2: 2 | O2: 19 | P2: 3335 | Q2: 1206 | R2: 2783 | S2: 3583 | T2: 997 | U2: 418 | V2: 1005 | W2: 448 | X2: 74 | Y2: 99 | Z2: 161 | AA2: 126 | AB2: 75 | AC2: 249
A3: 2 | B3: 43 | C3: 20 | D3: 25 | E3: 30 | F3: 24 | G3: 17 | H3: 48 | I3: 2 | J3: 1 | K3: 3 | L3: 5 | M3: 7 | N3: 2 | O3: 7 | P3: 4042 | Q3: 1182 | R3: 1674 | S3: 1938 | T3: 900 | U3: 422 | V3: 1101 | W3: 454 | X3: 79 | Y3: 83 | Z3: 168 | AA3: 138 | AB3: 79 | AC3: 269
A4: 3 | B4: 58 | C4: 17 | D4: 13 | E4: 18 | F4: 15 | G4: 23 | H4: 49 | I4: 2 | J4: 2 | K4: 1 | L4: 5 | M4: 4 | N4: 7 | O4: 12 | P4: 1445 | Q4: 461 | R4: 491 | S4: 588 | T4: 370 | U4: 195 | V4: 496 | W4: 552 | X4: 75 | Y4: 116 | Z4: 241 | AA4: 195 | AB4: 92 | AC4: 286
A5: 4 | B5: 19 | C5: 13 | D5: 12 | E5: 39 | F5: 42 | G5: 40 | H5: 166 | I5: 0 | J5: 1 | K5: 1 | L5: 7 | M5: 9 | N5: 12 | O5: 82 | P5: 1135 | Q5: 563 | R5: 859 | S5: 1616 | T5: 2282 | U5: 1490 | V5: 3095 | W5: 455 | X5: 84 | Y5: 175 | Z5: 350 | AA5: 314 | AB5: 156 | AC5: 590
A6: 5 | B6: 6 | C6: 3 | D6: 3 | E6: 25 | F6: 15 | G6: 13 | H6: 52 | I6: 2 | J6: 0 | K6: 3 | L6: 3 | M6: 5 | N6: 11 | O6: 33 | P6: 872 | Q6: 365 | R6: 546 | S6: 1077 | T6: 974 | U6: 450 | V6: 1264 | W6: 734 | X6: 117 | Y6: 158 | Z6: 383 | AA6: 294 | AB6: 154 | AC6: 555
A7: 6 | B7: 7 | C7: 4 | D7: 6 | E7: 11 | F7: 5 | G7: 4 | H7: 25 | I7: 2 | J7: 2 | K7: 0 | L7: 4 | M7: 5 | N7: 1 | O7: 9 | P7: 1061 | Q7: 453 | R7: 284 | S7: 402 | T7: 295 | U7: 117 | V7: 588 | W7: 472 | X7: 78 | Y7: 55 | Z7: 167 | AA7: 99 | AB7: 68 | AC7: 241
A8: 7 | B8: 2 | D8: 2 | E8: 22 | F8: 10 | G8: 13 | H8: 37 | I8: 1 | J8: 0 | K8: 1 | L8: 4 | M8: 2 | N8: 4 | O8: 14 | P8: 505 | Q8: 146 | R8: 358 | S8: 1037 | T8: 744 | U8: 381 | V8: 850 | W8: 160 | X8: 30 | Y8: 69 | Z8: 196 | AA8: 176 | AB8: 97 | AC8: 246
A9: 8 | B9: 3 | C9: 1 | D9: 10 | E9: 23 | F9: 17 | G9: 13 | H9: 62 | I9: 5 | J9: 0 | K9: 2 | L9: 4 | M9: 7 | N9: 7 | O9: 16 | P9: 258 | Q9: 177 | R9: 398 | S9: 1720 | T9: 1113 | U9: 622 | V9: 1281 | W9: 108 | X9: 28 | Y9: 74 | Z9: 144 | AA9: 104 | AB9: 68 | AC9: 207
A10: 9 | C10: 3 | D10: 19 | E10: 45 | F10: 32 | G10: 20 | H10: 99 | I10: 0 | J10: 0 | K10: 4 | L10: 5 | M10: 7 | N10: 9 | O10: 45 | P10: 291 | Q10: 338 | R10: 986 | S10: 2245 | T10: 1507 | U10: 906 | V10: 1666 | W10: 100 | X10: 55 | Y10: 125 | Z10: 227 | AA10: 124 | AB10: 97 | AC10: 330
A11: 10 | B11: 2 | D11: 2 | E11: 9 | F11: 10 | G11: 9 | H11: 20 | I11: 2 | J11: 1 | K11: 3 | L11: 0 | M11: 2 | N11: 3 | O11: 22 | P11: 1424 | Q11: 261 | R11: 411 | S11: 1638 | T11: 420 | U11: 602 | V11: 1058 | W11: 91 | X11: 70 | Y11: 124 | Z11: 223 | AA11: 145 | AB11: 76 | AC11: 330
A12: 11 | B12: 3 | D12: 5 | E12: 18 | F12: 5 | G12: 18 | H12: 21 | I12: 0 | J12: 0 | K12: 0 | L12: 1 | M12: 1 | N12: 3 | O12: 9 | P12: 1794 | Q12: 769 | R12: 540 | S12: 1603 | T12: 534 | U12: 779 | V12: 1648 | W12: 73 | X12: 64 | Y12: 76 | Z12: 203 | AA12: 136 | AB12: 102 | AC12: 340
A13: 12 | B13: 3 | C13: 5 | D13: 8 | E13: 12 | F13: 16 | G13: 11 | H13: 27 | I13: 1 | J13: 0 | K13: 0 | L13: 0 | M13: 6 | N13: 6 | O13: 9 | P13: 642 | Q13: 114 | R13: 315 | S13: 796 | T13: 270 | U13: 245 | V13: 701 | W13: 97 | X13: 37 | Y13: 69 | Z13: 149 | AA13: 168 | AB13: 80 | AC13: 261
A14: 13 | B14: 1 | C14: 1 | D14: 6 | E14: 18 | F14: 8 | G14: 4 | H14: 16 | I14: 0 | J14: 0 | K14: 0 | L14: 0 | M14: 0 | N14: 2 | O14: 5 | P14: 516 | Q14: 107 | R14: 244 | S14: 551 | T14: 446 | U14: 99 | V14: 646 | W14: 73 | X14: 20 | Y14: 51 | Z14: 83 | AA14: 46 | AB14: 45 | AC14: 137
A15: 14 | B15: 2 | C15: 1 | D15: 12 | E15: 15 | F15: 5 | G15: 7 | H15: 12 | I15: 2 | J15: 1 | K15: 0 | L15: 5 | M15: 1 | N15: 4 | O15: 4 | P15: 2188 | Q15: 631 | R15: 1279 | S15: 1636 | T15: 1405 | U15: 492 | V15: 2777 | W15: 118 | X15: 18 | Y15: 52 | Z15: 108 | AA15: 54 | AB15: 50 | AC15: 100
A16: 15 | C16: 1 | E16: 7 | F16: 10 | G16: 3 | H16: 11 | I16: 0 | J16: 0 | K16: 0 | L16: 0 | M16: 2 | N16: 5 | O16: 6 | P16: 243 | Q16: 47 | R16: 205 | S16: 457 | T16: 274 | U16: 105 | V16: 562 | W16: 54 | X16: 37 | Y16: 56 | Z16: 133 | AA16: 77 | AB16: 57 | AC16: 213
A17: 16 | B17: 4 | C17: 1 | D17: 4 | E17: 10 | F17: 14 | G17: 2 | H17: 9 | I17: 0 | J17: 0 | K17: 0 | L17: 2 | M17: 0 | N17: 8 | O17: 4 | P17: 159 | Q17: 79 | R17: 133 | S17: 283 | T17: 228 | U17: 104 | V17: 546 | W17: 136 | X17: 113 | Y17: 124 | Z17: 298 | AA17: 203 | AB17: 117 | AC17: 537
A18: 17 | B18: 5 | C18: 1 | D18: 5 | E18: 5 | F18: 2 | G18: 2 | H18: 8 | I18: 0 | J18: 1 | K18: 0 | L18: 1 | M18: 0 | N18: 0 | O18: 13 | P18: 110 | Q18: 59 | R18: 103 | S18: 305 | T18: 195 | U18: 111 | V18: 250 | W18: 209 | X18: 84 | Y18: 128 | Z18: 299 | AA18: 187 | AB18: 122 | AC18: 480
A19: 18 | B19: 6 | C19: 6 | D19: 1 | E19: 9 | F19: 3 | G19: 8 | H19: 27 | I19: 1 | J19: 0 | K19: 0 | L19: 0 | M19: 4 | N19: 3 | O19: 25 | P19: 133 | Q19: 92 | R19: 195 | S19: 387 | T19: 256 | U19: 152 | V19: 377 | W19: 134 | X19: 70 | Y19: 59 | Z19: 177 | AA19: 126 | AB19: 52 | AC19: 260
A20: 19 | B20: 2 | C20: 3 | D20: 2 | E20: 16 | F20: 4 | G20: 5 | H20: 5 | I20: 0 | J20: 0 | K20: 0 | L20: 0 | M20: 1 | N20: 2 | O20: 12 | P20: 105 | Q20: 44 | R20: 107 | S20: 251 | T20: 146 | U20: 72 | V20: 172 | W20: 64 | X20: 35 | Y20: 38 | Z20: 91 | AA20: 60 | AB20: 33 | AC20: 117
A21: 20 | B21: 4 | C21: 2 | D21: 2 | E21: 8 | F21: 5 | G21: 4 | H21: 7 | I21: 0 | J21: 0 | K21: 0 | L21: 0 | M21: 1 | N21: 3 | O21: 10 | P21: 170 | Q21: 66 | R21: 105 | S21: 313 | T21: 222 | U21: 120 | V21: 251 | W21: 48 | X21: 15 | Y21: 26 | Z21: 60 | AA21: 39 | AB21: 28 | AC21: 81
A22: 21 | B22: 5 | C22: 1 | D22: 7 | E22: 12 | F22: 11 | G22: 6 | H22: 19 | I22: 0 | J22: 1 | K22: 2 | L22: 3 | M22: 5 | N22: 4 | O22: 12 | P22: 216 | Q22: 117 | R22: 223 | S22: 467 | T22: 330 | U22: 179 | V22: 402 | W22: 57 | X22: 29 | Y22: 32 | Z22: 81 | AA22: 95 | AB22: 49 | AC22: 98
A23: 22 | B23: 3 | C23: 2 | D23: 9 | E23: 13 | F23: 10 | G23: 6 | H23: 26 | I23: 1 | J23: 0 | K23: 0 | L23: 5 | M23: 1 | N23: 4 | O23: 7 | P23: 333 | Q23: 141 | R23: 296 | S23: 622 | T23: 477 | U23: 215 | V23: 515 | W23: 55 | X23: 15 | Y23: 52 | Z23: 98 | AA23: 72 | AB23: 48 | AC23: 111
A24: 23 | B24: 4 | C24: 3 | D24: 2 | E24: 8 | F24: 6 | G24: 5 | H24: 25 | I24: 0 | J24: 0 | K24: 1 | L24: 0 | M24: 2 | N24: 3 | O24: 12 | P24: 257 | Q24: 172 | R24: 157 | S24: 432 | T24: 308 | U24: 132 | V24: 390 | W24: 60 | X24: 13 | Y24: 19 | Z24: 52 | AA24: 36 | AB24: 25 | AC24: 107
A25: 24 | B25: 1 | C25: 2 | D25: 1 | E25: 9 | F25: 4 | G25: 2 | H25: 16 | I25: 0 | J25: 0 | K25: 0 | L25: 0 | M25: 3 | N25: 0 | O25: 5 | P25: 134 | Q25: 54 | R25: 109 | S25: 293 | T25: 202 | U25: 92 | V25: 284 | W25: 65 | X25: 26 | Y25: 18 | Z25: 81 | AA25: 58 | AB25: 43 | AC25: 109
A26: 25 | B26: 1 | C26: 1 | D26: 2 | E26: 15 | F26: 2 | G26: 4 | H26: 7 | I26: 0 | J26: 0 | K26: 0 | L26: 0 | M26: 2 | N26: 0 | O26: 5 | P26: 141 | Q26: 45 | R26: 71 | S26: 171 | T26: 115 | U26: 100 | V26: 199 | W26: 46 | X26: 16 | Y26: 17 | Z26: 30 | AA26: 29 | AB26: 21 | AC26: 31
A27: 26 | B27: 3 | C27: 1 | D27: 1 | E27: 20 | F27: 9 | G27: 3 | H27: 5 | I27: 0 | J27: 0 | K27: 0 | L27: 1 | M27: 1 | N27: 2 | O27: 3 | P27: 81 | Q27: 100 | R27: 146 | S27: 345 | T27: 106 | U27: 299 | V27: 935 | W27: 26 | X27: 21 | Y27: 11 | Z27: 27 | AA27: 20 | AB27: 15 | AC27: 40
A28: 27 | B28: 1 | C28: 4 | E28: 8 | F28: 2 | G28: 1 | H28: 2 | I28: 1 | J28: 0 | K28: 0 | L28: 5 | M28: 0 | N28: 2 | O28: 5 | P28: 92 | Q28: 121 | R28: 222 | S28: 439 | T28: 116 | U28: 179 | V28: 670 | W28: 41 | X28: 10 | Y28: 8 | Z28: 18 | AA28: 28 | AB28: 6 | AC28: 37
A29: 28 | B29: 1 | C29: 2 | E29: 4 | F29: 1 | H29: 4 | I29: 0 | J29: 0 | K29: 0 | L29: 1 | M29: 0 | N29: 0 | O29: 3 | P29: 67 | Q29: 47 | R29: 108 | S29: 126 | T29: 62 | U29: 42 | V29: 203 | W29: 33 | X29: 7 | Y29: 5 | Z29: 21 | AA29: 14 | AB29: 8 | AC29: 35
A30: 29 | B30: 1 | C30: 3 | F30: 1 | G30: 1 | H30: 3 | I30: 0 | J30: 0 | K30: 0 | L30: 0 | M30: 2 | N30: 1 | O30: 1 | P30: 39 | Q30: 14 | R30: 35 | S30: 63 | T30: 47 | U30: 18 | V30: 75 | W30: 35 | X30: 4 | Y30: 14 | Z30: 25 | AA30: 20 | AB30: 15 | AC30: 39
A31: 30 | B31: 1 | E31: 3 | F31: 3 | G31: 2 | H31: 6 | I31: 0 | J31: 0 | K31: 0 | L31: 1 | M31: 1 | N31: 0 | O31: 5 | P31: 53 | Q31: 30 | R31: 30 | S31: 114 | T31: 80 | U31: 45 | V31: 75 | W31: 65 | X31: 22 | Y31: 16 | Z31: 47 | AA31: 28 | AB31: 19 | AC31: 83
A32: 31 | B32: 1 | D32: 2 | E32: 6 | F32: 6 | G32: 2 | H32: 13 | I32: 0 | J32: 0 | K32: 0 | L32: 0 | M32: 0 | N32: 0 | O32: 17 | P32: 89 | Q32: 32 | R32: 56 | S32: 130 | T32: 111 | U32: 50 | V32: 136 | W32: 60 | X32: 11 | Y32: 27 | Z32: 56 | AA32: 33 | AB32: 16 | AC32: 132
A33: 32 | D33: 1 | E33: 6 | F33: 4 | G33: 1 | H33: 14 | I33: 0 | J33: 0 | K33: 0 | L33: 2 | M33: 1 | N33: 2 | O33: 17 | P33: 228 | Q33: 77 | R33: 123 | S33: 227 | T33: 186 | U33: 90 | V33: 170 | W33: 53 | X33: 26 | Y33: 29 | Z33: 82 | AA33: 52 | AB33: 42 | AC33: 141
A34: 33 | B34: 2 | D34: 4 | E34: 3 | F34: 2 | G34: 2 | H34: 11 | I34: 1 | J34: 0 | K34: 0 | L34: 0 | M34: 0 | N34: 1 | O34: 6 | P34: 183 | Q34: 56 | R34: 73 | S34: 181 | T34: 165 | U34: 64 | V34: 164 | W34: 67 | X34: 13 | Y34: 35 | Z34: 85 | AA34: 58 | AB34: 16 | AC34: 145
A35: 34 | B35: 3 | E35: 4 | G35: 4 | H35: 7 | I35: 0 | J35: 0 | K35: 0 | L35: 0 | M35: 0 | N35: 0 | O35: 8 | P35: 173 | Q35: 43 | R35: 109 | S35: 123 | T35: 154 | U35: 67 | V35: 267 | W35: 63 | X35: 12 | Y35: 26 | Z35: 77 | AA35: 71 | AB35: 38 | AC35: 134
A36: 35 | B36: 1 | D36: 4 | E36: 4 | F36: 5 | G36: 1 | H36: 7 | I36: 0 | J36: 0 | K36: 2 | L36: 0 | M36: 1 | N36: 0 | O36: 4 | P36: 152 | Q36: 55 | R36: 127 | S36: 207 | T36: 138 | U36: 58 | V36: 235 | W36: 39 | X36: 11 | Y36: 36 | Z36: 74 | AA36: 38 | AB36: 29 | AC36: 132
A37: 36 | B37: 1 | D37: 3 | E37: 1 | F37: 1 | G37: 3 | H37: 8 | I37: 0 | J37: 0 | K37: 0 | L37: 0 | M37: 0 | N37: 0 | O37: 5 | P37: 134 | Q37: 34 | R37: 136 | S37: 157 | T37: 180 | U37: 65 | V37: 145 | W37: 62 | X37: 6 | Y37: 20 | Z37: 65 | AA37: 34 | AB37: 23 | AC37: 94
A38: 37 | B38: 2 | D38: 1 | E38: 3 | G38: 2 | H38: 8 | I38: 1 | J38: 0 | K38: 1 | L38: 0 | M38: 1 | N38: 0 | O38: 1 | P38: 172 | Q38: 59 | R38: 125 | S38: 227 | T38: 205 | U38: 112 | V38: 253 | W38: 67 | X38: 36 | Y38: 63 | Z38: 119 | AA38: 70 | AB38: 66 | AC38: 173
A39: 38 | B39: 2 | C39: 1 | D39: 1 | E39: 4 | F39: 3 | G39: 3 | H39: 7 | I39: 0 | J39: 0 | K39: 0 | L39: 2 | M39: 0 | N39: 2 | O39: 5 | P39: 135 | Q39: 48 | R39: 102 | S39: 204 | T39: 190 | U39: 94 | V39: 190 | W39: 29 | X39: 13 | Y39: 17 | Z39: 42 | AA39: 22 | AB39: 15 | AC39: 72
A40: 39 | B40: 2 | D40: 4 | E40: 3 | F40: 3 | G40: 3 | H40: 8 | I40: 0 | J40: 2 | K40: 0 | L40: 1 | M40: 0 | N40: 1 | O40: 6 | P40: 355 | Q40: 110 | R40: 266 | S40: 531 | T40: 479 | U40: 256 | V40: 867 | W40: 32 | X40: 10 | Y40: 33 | Z40: 45 | AA40: 27 | AB40: 19 | AC40: 51
...

Sheet Sheet1

Sheet UPS RATES
A2: Wgt | B2: 2Day*2 | C2: 2Day*3 | D2: 2Day*4 | E2: 2Day*5 | F2: 2Day*6 | G2: 2Day*7 | H2: 2Day*8 | I2: 3Day*2 | J2: 3Day*3 | K2: 3Day*4 | L2: 3Day*5 | M2: 3Day*6 | N2: 3Day*7 | O2: 3Day*8 | P2: Ground*2 | Q2: Ground*3 | R2: Ground*4 | S2: Ground*5 | T2: Ground*6 | U2: Ground*7 | V2: Ground*8 | W2: Next Day AM*2 | X2: Next Day AM*3 | Y2: Next Day AM*4 | Z2: Next Day AM*5 | AA2: Next Day AM*6 | AB2: Next Day AM*7 | AC2: Next Day AM*8
A3: 1 | B3: 8.06 | C3: 8.06 | D3: 8.06 | E3: 8.06 | F3: 8.09 | G3: 8.63 | H3: 8.8 | I3: 8.24 | J3: 8.24 | K3: 8.24 | L3: 8.24 | M3: 8.98 | N3: 9.87 | O3: 10.7 | P3: 7.53 | Q3: 7.53 | R3: 7.53 | S3: 7.53 | T3: 7.53 | U3: 7.53 | V3: 7.53 | W3: 11.33 | X3: 11.33 | Y3: 13.02 | Z3: 14.4 | AA3: 15.16 | AB3: 17.22 | AC3: 17.69
A4: 2 | B4: 8.06 | C4: 8.06 | D4: 8.06 | E4: 8.06 | F4: 9.1 | G4: 10.09 | H4: 10.62 | I4: 8.24 | J4: 8.24 | K4: 8.24 | L4: 8.24 | M4: 9.93 | N4: 11.06 | O4: 12.58 | P4: 7.53 | Q4: 7.53 | R4: 7.53 | S4: 7.53 | T4: 7.53 | U4: 7.64 | V4: 7.78 | W4: 11.33 | X4: 11.33 | Y4: 14.23 | Z4: 15.46 | AA4: 15.93 | AB4: 17.93 | AC4: 19.77
A5: 3 | B5: 8.06 | C5: 8.06 | D5: 8.06 | E5: 8.06 | F5: 10.46 | G5: 11.7 | H5: 12.18 | I5: 8.24 | J5: 8.24 | K5: 8.24 | L5: 8.92 | M5: 11.58 | N5: 12.37 | O5: 14.35 | P5: 7.53 | Q5: 7.53 | R5: 7.53 | S5: 7.58 | T5: 7.89 | U5: 8.15 | V5: 8.56 | W5: 11.33 | X5: 11.33 | Y5: 15.76 | Z5: 17.67 | AA5: 19.01 | AB5: 20.87 | AC5: 21.61
A6: 4 | B6: 8.06 | C6: 8.06 | D6: 8.06 | E6: 9.33 | F6: 12.06 | G6: 13.33 | H6: 13.84 | I6: 8.24 | J6: 8.24 | K6: 8.24 | L6: 9.99 | M6: 12.23 | N6: 14.02 | O6: 15.89 | P6: 7.53 | Q6: 7.53 | R6: 7.53 | S6: 7.99 | T6: 8.22 | U6: 8.76 | V6: 9.16 | W6: 11.33 | X6: 11.37 | Y6: 17.62 | Z6: 19.35 | AA6: 20.06 | AB6: 22.67 | AC6: 23.52
A7: 5 | B7: 8.06 | C7: 8.06 | D7: 8.06 | E7: 10.34 | F7: 13.47 | G7: 14.82 | H7: 15.71 | I7: 8.24 | J7: 8.24 | K7: 8.24 | L7: 10.92 | M7: 13.65 | N7: 15.5 | O7: 17.54 | P7: 7.53 | Q7: 7.53 | R7: 7.7 | S7: 8.35 | T7: 8.69 | U7: 9.16 | V7: 9.71 | W7: 11.33 | X7: 11.43 | Y7: 17.99 | Z7: 19.53 | AA7: 20.24 | AB7: 22.96 | AC7: 23.62
A8: 6 | B8: 8.06 | C8: 8.06 | D8: 8.12 | E8: 11.29 | F8: 14.94 | G8: 16.47 | H8: 17.2 | I8: 8.24 | J8: 8.24 | K8: 8.65 | L8: 11.93 | M8: 15.67 | N8: 17.2 | O8: 18.99 | P8: 7.53 | Q8: 7.53 | R8: 7.53 | S8: 8.07 | T8: 8.36 | U8: 8.82 | V8: 9.35 | W8: 11.33 | X8: 12.62 | Y8: 20.23 | Z8: 22.84 | AA8: 23.89 | AB8: 26.36 | AC8: 27.49
A9: 7 | B9: 8.06 | C9: 8.06 | D9: 8.8 | E9: 12.34 | F9: 16.81 | G9: 18.21 | H9: 18.91 | I9: 8.24 | J9: 8.34 | K9: 9.39 | L9: 12.71 | M9: 16.97 | N9: 19.43 | O9: 20.89 | P9: 7.53 | Q9: 7.53 | R9: 7.67 | S9: 8.33 | T9: 8.52 | U9: 9.05 | V9: 9.7 | W9: 11.33 | X9: 13.27 | Y9: 21.14 | Z9: 23.96 | AA9: 24.87 | AB9: 27.51 | AC9: 29.37
A10: 8 | B10: 8.06 | C10: 8.06 | D10: 9.41 | E10: 13.46 | F10: 18.56 | G10: 20.06 | H10: 20.82 | I10: 8.24 | J10: 9.01 | K10: 10.14 | L10: 13.61 | M10: 18.23 | N10: 20.86 | O10: 22.75 | P10: 7.53 | Q10: 7.53 | R10: 7.94 | S10: 8.56 | T10: 8.86 | U10: 9.42 | V10: 10.11 | W10: 11.33 | X10: 13.34 | Y10: 21.94 | Z10: 24.89 | AA10: 26.04 | AB10: 29.13 | AC10: 30.28
A11: 9 | B11: 8.06 | C11: 8.2 | D11: 10.17 | E11: 14.45 | F11: 20.16 | G11: 22 | H11: 22.82 | I11: 8.24 | J11: 9.42 | K11: 10.78 | L11: 13.87 | M11: 18.85 | N11: 22.2 | O11: 24.48 | P11: 7.53 | Q11: 7.53 | R11: 7.97 | S11: 8.64 | T11: 9.05 | U11: 9.81 | V11: 10.65 | W11: 11.33 | X11: 13.44 | Y11: 22.84 | Z11: 24.99 | AA11: 26.16 | AB11: 29.3 | AC11: 30.38
A12: 10 | B12: 8.06 | C12: 8.74 | D12: 10.95 | E12: 15.44 | F12: 21.6 | G12: 23.93 | H12: 24.71 | I12: 8.24 | J12: 9.71 | K12: 10.99 | L12: 14.73 | M12: 19.82 | N12: 23.9 | O12: 26.24 | P12: 7.53 | Q12: 7.53 | R12: 8.05 | S12: 8.85 | T12: 9.15 | U12: 10.28 | V12: 11.35 | W12: 11.33 | X12: 13.61 | Y12: 23.09 | Z12: 25.21 | AA12: 26.52 | AB12: 29.58 | AC12: 30.64
A13: 11 | B13: 8.06 | C13: 9.22 | D13: 11.46 | E13: 16.51 | F13: 23.27 | G13: 25.69 | H13: 26.75 | I13: 8.3 | J13: 9.97 | K13: 11.99 | L13: 15.42 | M13: 21.87 | N13: 25.17 | O13: 27.82 | P13: 7.53 | Q13: 7.53 | R13: 7.83 | S13: 8.52 | T13: 9.01 | U13: 10.62 | V13: 11.53 | W13: 11.37 | X13: 16.02 | Y13: 28.16 | Z13: 31.99 | AA13: 33.62 | AB13: 35.24 | AC13: 35.94
A14: 12 | B14: 8.08 | C14: 9.76 | D14: 12.09 | E14: 17.44 | F14: 25.07 | G14: 27.55 | H14: 28.31 | I14: 8.75 | J14: 10.96 | K14: 12.49 | L14: 16.99 | M14: 23.29 | N14: 26.4 | O14: 29.51 | P14: 7.53 | Q14: 7.53 | R14: 7.91 | S14: 8.62 | T14: 9.33 | U14: 11.04 | V14: 12.07 | W14: 11.64 | X14: 16.55 | Y14: 28.8 | Z14: 33.49 | AA14: 35.15 | AB14: 35.97 | AC14: 36.7
... A101: 99 | B101: 39.7 | C101: 46 | D101: 57.8 | E101: 86.72 | F101: 142.72 | G101: 149.55 | H101: 155.79 | I101: 40.79 | J101: 49.94 | K101: 62.26 | L101: 90.73 | M101: 127.96 | N101: 150.63 | O101: 172.24 | P101: 28 | Q101: 28.04 | R101: 30.75 | S101: 33.12 | T101: 38.45 | U101: 42.95 | V101: 47.32 | W101: 48.02 | X101: 67.49 | Y101: 121.18 | Z101: 139.32 | AA101: 142.8 | AB101: 165.59 | AC101: 168.2

Sheet UPS TOTAL SPEND
A1: Wgt | B1: 2Day*2 | C1: 2Day*3 | D1: 2Day*4 | E1: 2Day*5 | F1: 2Day*6 | G1: 2Day*7 | H1: 2Day*8 | I1: 3Day*2 | J1: 3Day*3 | K1: 3Day*4 | L1: 3Day*5 | M1: 3Day*6 | N1: 3Day*7 | O1: 3Day*8 | P1: Ground*2 | Q1: Ground*3 | R1: Ground*4 | S1: Ground*5 | T1: Ground*6 | U1: Ground*7 | V1: Ground*8 | W1: Next Day AM*2 | X1: Next Day AM*3 | Y1: Next Day AM*4 | Z1: Next Day AM*5 | AA1: Next Day AM*6 | AB1: Next Day AM*7 | AC1: Next Day AM*8
A2: 1 | B2: =SUM('TOTAL VOLUME'!B2*'UPS RATES'!B3) -> 459.42 | C2: =SUM('TOTAL VOLUME'!C2*'UPS RATES'!C3) -> 145.08 | D2: =SUM('TOTAL VOLUME'!D2*'UPS RATES'!D3) -> 314.34 | E2: =SUM('TOTAL VOLUME'!E2*'UPS RATES'!E3) -> 314.34 | F2: =SUM('TOTAL VOLUME'!F2*'UPS RATES'!F3) -> 234.61 | G2: =SUM('TOTAL VOLUME'!G2*'UPS RATES'!G3) -> 77.67 | H2: =SUM('TOTAL VOLUME'!H2*'UPS RATES'!H3) -> 299.2 | I2: =SUM('TOTAL VOLUME'!I2*'UPS RATES'!I3) -> 74.16 | ... AC2: =SUM('TOTAL VOLUME'!AC2*'UPS RATES'!AC3) -> 4404.81
A3: 2 | B3: =SUM('TOTAL VOLUME'!B3*'UPS RATES'!B4) -> 346.58 | C3: =SUM('TOTAL VOLUME'!C3*'UPS RATES'!C4) -> 161.2 | D3: =SUM('TOTAL VOLUME'!D3*'UPS RATES'!D4) -> 201.5 | E3: =SUM('TOTAL VOLUME'!E3*'UPS RATES'!E4) -> 241.8 | F3: =SUM('TOTAL VOLUME'!F3*'UPS RATES'!F4) -> 218.4 | G3: =SUM('TOTAL VOLUME'!G3*'UPS RATES'!G4) -> 171.53 | H3: =SUM('TOTAL VOLUME'!H3*'UPS RATES'!H4) -> 509.76 | I3: =SUM('TOTAL VOLUME'!I3*'UPS RATES'!I4) -> 16.48 | ... AC3: =SUM('TOTAL VOLUME'!AC3*'UPS RATES'!AC4) -> 5318.13
A4: 3 | B4: =SUM('TOTAL VOLUME'!B4*'UPS RATES'!B5) -> 467.48 | C4: =SUM('TOTAL VOLUME'!C4*'UPS RATES'!C5) -> 137.02 | D4: =SUM('TOTAL VOLUME'!D4*'UPS RATES'!D5) -> 104.78 | E4: =SUM('TOTAL VOLUME'!E4*'UPS RATES'!E5) -> 145.08 | F4: =SUM('TOTAL VOLUME'!F4*'UPS RATES'!F5) -> 156.9 | G4: =SUM('TOTAL VOLUME'!G4*'UPS RATES'!G5) -> 269.1 | H4: =SUM('TOTAL VOLUME'!H4*'UPS RATES'!H5) -> 596.82 | I4: =SUM('TOTAL VOLUME'!I4*'UPS RATES'!I5) -> 16.48 | ... AC4: =SUM('TOTAL VOLUME'!AC4*'UPS RATES'!AC5) -> 6180.46
A5: 4 | B5: =SUM('TOTAL VOLUME'!B5*'UPS RATES'!B6) -> 153.14 | C5: =SUM('TOTAL VOLUME'!C5*'UPS RATES'!C6) -> 104.78 | D5: =SUM('TOTAL VOLUME'!D5*'UPS RATES'!D6) -> 96.72 | E5: =SUM('TOTAL VOLUME'!E5*'UPS RATES'!E6) -> 363.87 | F5: =SUM('TOTAL VOLUME'!F5*'UPS RATES'!F6) -> 506.52 | G5: =SUM('TOTAL VOLUME'!G5*'UPS RATES'!G6) -> 533.2 | H5: =SUM('TOTAL VOLUME'!H5*'UPS RATES'!H6) -> 2297.44 | I5: =SUM('TOTAL VOLUME'!I5*'UPS RATES'!I6) -> 0 | ... AC5: =SUM('TOTAL VOLUME'!AC5*'UPS RATES'!AC6) -> 13876.8
A6: 5 | B6: =SUM('TOTAL VOLUME'!B6*'UPS RATES'!B7) -> 48.36 | C6: =SUM('TOTAL VOLUME'!C6*'UPS RATES'!C7) -> 24.18 | D6: =SUM('TOTAL VOLUME'!D6*'UPS RATES'!D7) -> 24.18 | E6: =SUM('TOTAL VOLUME'!E6*'UPS RATES'!E7) -> 258.5 | F6: =SUM('TOTAL VOLUME'!F6*'UPS RATES'!F7) -> 202.05 | G6: =SUM('TOTAL VOLUME'!G6*'UPS RATES'!G7) -> 192.66 | H6: =SUM('TOTAL VOLUME'!H6*'UPS RATES'!H7) -> 816.92 | I6: =SUM('TOTAL VOLUME'!I6*'UPS RATES'!I7) -> 16.48 | ... AC6: =SUM('TOTAL VOLUME'!AC6*'UPS RATES'!AC7) -> 13109.1
A7: 6 | B7: =SUM('TOTAL VOLUME'!B7*'UPS RATES'!B8) -> 56.42 | C7: =SUM('TOTAL VOLUME'!C7*'UPS RATES'!C8) -> 32.24 | D7: =SUM('TOTAL VOLUME'!D7*'UPS RATES'!D8) -> 48.72 | E7: =SUM('TOTAL VOLUME'!E7*'UPS RATES'!E8) -> 124.19 | F7: =SUM('TOTAL VOLUME'!F7*'UPS RATES'!F8) -> 74.7 | G7: =SUM('TOTAL VOLUME'!G7*'UPS RATES'!G8) -> 65.88 | H7: =SUM('TOTAL VOLUME'!H7*'UPS RATES'!H8) -> 430 | I7: =SUM('TOTAL VOLUME'!I7*'UPS RATES'!I8) -> 16.48 | ... AC7: =SUM('TOTAL VOLUME'!AC7*'UPS RATES'!AC8) -> 6625.09
A8: 7 | B8: =SUM('TOTAL VOLUME'!B8*'UPS RATES'!B9) -> 16.12 | C8: =SUM('TOTAL VOLUME'!C8*'UPS RATES'!C9) -> 0 | D8: =SUM('TOTAL VOLUME'!D8*'UPS RATES'!D9) -> 17.6 | E8: =SUM('TOTAL VOLUME'!E8*'UPS RATES'!E9) -> 271.48 | F8: =SUM('TOTAL VOLUME'!F8*'UPS RATES'!F9) -> 168.1 | G8: =SUM('TOTAL VOLUME'!G8*'UPS RATES'!G9) -> 236.73 | H8: =SUM('TOTAL VOLUME'!H8*'UPS RATES'!H9) -> 699.67 | I8: =SUM('TOTAL VOLUME'!I8*'UPS RATES'!I9) -> 8.24 | ... AC8: =SUM('TOTAL VOLUME'!AC8*'UPS RATES'!AC9) -> 7225.02
A9: 8 | B9: =SUM('TOTAL VOLUME'!B9*'UPS RATES'!B10) -> 24.18 | C9: =SUM('TOTAL VOLUME'!C9*'UPS RATES'!C10) -> 8.06 | D9: =SUM('TOTAL VOLUME'!D9*'UPS RATES'!D10) -> 94.1 | E9: =SUM('TOTAL VOLUME'!E9*'UPS RATES'!E10) -> 309.58 | F9: =SUM('TOTAL VOLUME'!F9*'UPS RATES'!F10) -> 315.52 | G9: =SUM('TOTAL VOLUME'!G9*'UPS RATES'!G10) -> 260.78 | H9: =SUM('TOTAL VOLUME'!H9*'UPS RATES'!H10) -> 1290.84 | I9: =SUM('TOTAL VOLUME'!I9*'UPS RATES'!I10) -> 41.2 | ... AC9: =SUM('TOTAL VOLUME'!AC9*'UPS RATES'!AC10) -> 6267.96
A10: 9 | B10: =SUM('TOTAL VOLUME'!B10*'UPS RATES'!B11) -> 0 | C10: =SUM('TOTAL VOLUME'!C10*'UPS RATES'!C11) -> 24.6 | D10: =SUM('TOTAL VOLUME'!D10*'UPS RATES'!D11) -> 193.23 | E10: =SUM('TOTAL VOLUME'!E10*'UPS RATES'!E11) -> 650.25 | F10: =SUM('TOTAL VOLUME'!F10*'UPS RATES'!F11) -> 645.12 | G10: =SUM('TOTAL VOLUME'!G10*'UPS RATES'!G11) -> 440 | H10: =SUM('TOTAL VOLUME'!H10*'UPS RATES'!H11) -> 2259.18 | I10: =SUM('TOTAL VOLUME'!I10*'UPS RATES'!I11) -> 0 | ... AC10: =SUM('TOTAL VOLUME'!AC10*'UPS RATES'!AC11) -> 10025.4
A11: 10 | B11: =SUM('TOTAL VOLUME'!B11*'UPS RATES'!B12) -> 16.12 | C11: =SUM('TOTAL VOLUME'!C11*'UPS RATES'!C12) -> 0 | D11: =SUM('TOTAL VOLUME'!D11*'UPS RATES'!D12) -> 21.9 | E11: =SUM('TOTAL VOLUME'!E11*'UPS RATES'!E12) -> 138.96 | F11: =SUM('TOTAL VOLUME'!F11*'UPS RATES'!F12) -> 216 | G11: =SUM('TOTAL VOLUME'!G11*'UPS RATES'!G12) -> 215.37 | H11: =SUM('TOTAL VOLUME'!H11*'UPS RATES'!H12) -> 494.2 | I11: =SUM('TOTAL VOLUME'!I11*'UPS RATES'!I12) -> 16.48 | ... AC11: =SUM('TOTAL VOLUME'!AC11*'UPS RATES'!AC12) -> 10111.2
A12: 11 | B12: =SUM('TOTAL VOLUME'!B12*'UPS RATES'!B13) -> 24.18 | C12: =SUM('TOTAL VOLUME'!C12*'UPS RATES'!C13) -> 0 | D12: =SUM('TOTAL VOLUME'!D12*'UPS RATES'!D13) -> 57.3 | E12: =SUM('TOTAL VOLUME'!E12*'UPS RATES'!E13) -> 297.18 | F12: =SUM('TOTAL VOLUME'!F12*'UPS RATES'!F13) -> 116.35 | G12: =SUM('TOTAL VOLUME'!G12*'UPS RATES'!G13) -> 462.42 | H12: =SUM('TOTAL VOLUME'!H12*'UPS RATES'!H13) -> 561.75 | I12: =SUM('TOTAL VOLUME'!I12*'UPS RATES'!I13) -> 0 | ... AC12: =SUM('TOTAL VOLUME'!AC12*'UPS RATES'!AC13) -> 12219.6
A13: 12 | B13: =SUM('TOTAL VOLUME'!B13*'UPS RATES'!B14) -> 24.24 | C13: =SUM('TOTAL VOLUME'!C13*'UPS RATES'!C14) -> 48.8 | D13: =SUM('TOTAL VOLUME'!D13*'UPS RATES'!D14) -> 96.72 | E13: =SUM('TOTAL VOLUME'!E13*'UPS RATES'!E14) -> 209.28 | F13: =SUM('TOTAL VOLUME'!F13*'UPS RATES'!F14) -> 401.12 | G13: =SUM('TOTAL VOLUME'!G13*'UPS RATES'!G14) -> 303.05 | H13: =SUM('TOTAL VOLUME'!H13*'UPS RATES'!H14) -> 764.37 | I13: =SUM('TOTAL VOLUME'!I13*'UPS RATES'!I14) -> 8.75 | ... AC13: =SUM('TOTAL VOLUME'!AC13*'UPS RATES'!AC14) -> 9578.7
... A100: 99 | B100: =SUM('TOTAL VOLUME'!B100*'UPS RATES'!B101) -> 0 | C100: =SUM('TOTAL VOLUME'!C100*'UPS RATES'!C101) -> 0 | D100: =SUM('TOTAL VOLUME'!D100*'UPS RATES'!D101) -> 0 | E100: =SUM('TOTAL VOLUME'!E100*'UPS RATES'!E101) -> 0 | F100: =SUM('TOTAL VOLUME'!F100*'UPS RATES'!F101) -> 0 | G100: =SUM('TOTAL VOLUME'!G100*'UPS RATES'!G101) -> 0 | H100: =SUM('TOTAL VOLUME'!H100*'UPS RATES'!H101) -> 0 | I100: =SUM('TOTAL VOLUME'!I100*'UPS RATES'!I101) -> 0 | ... AC100: =SUM('TOTAL VOLUME'!AC100*'UPS RATES'!AC101) -> 0
B101: =SUM(B2:B100) -> 2922.92 | C101: =SUM(C2:C100) -> 1549.37 | D101: =SUM(D2:D100) -> 3338.11 | E101: =SUM(E2:E100) -> 11218.31 | F101: =SUM(F2:F100) -> 10043.56 | G101: =SUM(G2:G100) -> 8821.5 | H101: =SUM(H2:H100) -> 31159.89 | I101: =SUM(I2:I100) -> 398.75 | ... AC101: =SUM(AC2:AC100) -> 372921.34
B102: Total UPS | P102: =SUM(#REF!) -> #REF!
A103: 6 mos | B103: =SUM(B101:AE101) -> 2763003.6

Sheet FedEx Rates
A1: Wgt | B1: 2Day*2 | C1: 2Day*3 | D1: 2Day*4 | E1: 2Day*5 | F1: 2Day*6 | G1: 2Day*7 | H1: 2Day*8 | I1: 3Day*2 | J1: 3Day*3 | K1: 3Day*4 | L1: 3Day*5 | M1: 3Day*6 | N1: 3Day*7 | O1: 3Day*8 | P1: Ground*2 | Q1: Ground*3 | R1: Ground*4 | S1: Ground*5 | T1: Ground*6 | U1: Ground*7 | V1: Ground*8 | W1: Next Day AM*2 | X1: Next Day AM*3 | Y1: Next Day AM*4 | Z1: Next Day AM*5 | AA1: Next Day AM*6 | AB1: Next Day AM*7 | AC1: Next Day AM*8
A2: 1 | B2: 6.11 | C2: 6.11 | D2: 6.11 | E2: 6.11 | F2: 6.11 | G2: 6.11 | H2: 6.11 | I2: 5.87 | J2: 5.87 | K2: 5.87 | L2: 5.87 | M2: 5.87 | N2: 5.87 | O2: 6.07 | P2: 6.25 | Q2: 6.25 | R2: 6.25 | S2: 6.25 | T2: 6.25 | U2: 6.25 | V2: 6.25 | W2: 7.81 | X2: 7.81 | Y2: 7.81 | Z2: 7.81 | AA2: 7.81 | AB2: 8.20 | AC2: 8.42
A3: 2 | B3: 6.11 | C3: 6.11 | D3: 6.11 | E3: 6.11 | F3: 6.11 | G3: 6.11 | H3: 6.11 | I3: 5.87 | J3: 5.87 | K3: 5.87 | L3: 5.87 | M3: 5.87 | N3: 6.09 | O3: 7.05 | P3: 6.25 | Q3: 6.25 | R3: 6.25 | S3: 6.25 | T3: 6.25 | U3: 6.25 | V3: 6.25 | W3: 7.81 | X3: 7.81 | Y3: 7.81 | Z3: 7.81 | AA3: 7.81 | AB3: 8.54 | AC3: 9.41
A4: 3 | B4: 6.11 | C4: 6.11 | D4: 6.11 | E4: 6.11 | F4: 7.89 | G4: 8.83 | H4: 9.21 | I4: 5.87 | J4: 5.87 | K4: 5.87 | L4: 5.87 | M4: 6.45 | N4: 6.82 | O4: 7.96 | P4: 6.25 | Q4: 6.25 | R4: 6.25 | S4: 6.25 | T4: 6.25 | U4: 6.25 | V4: 6.25 | W4: 7.81 | X4: 7.81 | Y4: 7.81 | Z4: 8.42 | AA4: 9.05 | AB4: 9.94 | AC4: 10.29
A5: 4 | B5: 6.11 | C5: 6.11 | D5: 6.11 | E5: 7.09 | F5: 9.12 | G5: 10.09 | H5: 10.48 | I5: 5.87 | J5: 5.87 | K5: 5.87 | L5: 5.87 | M5: 6.79 | N5: 7.79 | O5: 9.11 | P5: 6.25 | Q5: 6.25 | R5: 6.25 | S5: 6.25 | T5: 6.25 | U5: 6.25 | V5: 6.25 | W5: 7.81 | X5: 7.81 | Y5: 8.39 | Z5: 9.21 | AA5: 9.55 | AB5: 10.79 | AC5: 11.20
A6: 5 | B6: 6.11 | C6: 6.11 | D6: 6.11 | E6: 7.87 | F6: 10.19 | G6: 11.24 | H6: 11.92 | I6: 5.87 | J6: 5.87 | K6: 5.87 | L6: 6.01 | M6: 7.70 | N6: 8.60 | O6: 10.21 | P6: 6.25 | Q6: 6.25 | R6: 6.25 | S6: 6.25 | T6: 6.25 | U6: 6.25 | V6: 6.46 | W6: 7.81 | X6: 7.81 | Y6: 8.57 | Z6: 9.30 | AA6: 9.64 | AB6: 10.94 | AC6: 11.29
A7: 6 | B7: 6.11 | C7: 6.11 | D7: 6.12 | E7: 8.60 | F7: 11.32 | G7: 12.49 | H7: 13.05 | I7: 5.87 | J7: 5.87 | K7: 5.87 | L7: 7.08 | M7: 9.05 | N7: 9.56 | O7: 11.62 | P7: 6.25 | Q7: 6.25 | R7: 6.25 | S7: 6.25 | T7: 6.25 | U7: 6.25 | V7: 6.46 | W7: 7.81 | X7: 7.81 | Y7: 9.64 | Z7: 10.87 | AA7: 11.38 | AB7: 12.55 | AC7: 13.09
A8: 7 | B8: 6.11 | C8: 6.11 | D8: 6.63 | E8: 9.40 | F8: 12.74 | G8: 13.86 | H8: 14.38 | I8: 5.87 | J8: 5.87 | K8: 6.19 | L8: 7.22 | M8: 9.54 | N8: 10.81 | O8: 12.10 | P8: 6.25 | Q8: 6.25 | R8: 6.25 | S8: 6.25 | T8: 6.25 | U8: 6.26 | V8: 6.70 | W8: 7.81 | X8: 7.81 | Y8: 10.07 | Z8: 11.41 | AA8: 11.84 | AB8: 13.10 | AC8: 13.99
A9: 8 | B9: 6.11 | C9: 6.11 | D9: 7.10 | E9: 10.25 | F9: 14.09 | G9: 15.27 | H9: 15.83 | I9: 5.87 | J9: 5.87 | K9: 6.40 | L9: 7.76 | M9: 10.48 | N9: 11.83 | O9: 13.22 | P9: 6.25 | Q9: 6.25 | R9: 6.25 | S9: 6.25 | T9: 6.25 | U9: 6.51 | V9: 6.99 | W9: 7.81 | X9: 7.81 | Y9: 10.51 | Z9: 11.85 | AA9: 12.40 | AB9: 13.87 | AC9: 14.43
A10: 9 | B10: 6.11 | C10: 6.24 | D10: 7.67 | E10: 11.00 | F10: 15.33 | G10: 16.75 | H10: 17.37 | I10: 5.87 | J10: 5.87 | K10: 6.83 | L10: 8.08 | M10: 10.82 | N10: 12.98 | O10: 15.01 | P10: 6.25 | Q10: 6.25 | R10: 6.25 | S10: 6.25 | T10: 6.26 | U10: 6.78 | V10: 7.37 | W10: 7.81 | X10: 7.81 | Y10: 10.87 | Z10: 11.89 | AA10: 12.46 | AB10: 13.95 | AC10: 14.47
A11: 10 | B11: 6.11 | C11: 6.66 | D11: 8.26 | E11: 11.75 | F11: 16.37 | G11: 18.22 | H11: 18.79 | I11: 5.87 | J11: 5.87 | K11: 7.01 | L11: 8.68 | M11: 11.49 | N11: 13.97 | O11: 16.18 | P11: 6.25 | Q11: 6.25 | R11: 6.25 | S11: 6.25 | T11: 6.33 | U11: 7.10 | V11: 7.85 | W11: 7.81 | X11: 7.81 | Y11: 11.00 | Z11: 12.07 | AA11: 12.63 | AB11: 14.09 | AC11: 14.60
A12: 11 | B12: 6.11 | C12: 7.01 | D12: 8.64 | E12: 12.57 | F12: 17.67 | G12: 19.53 | H12: 20.36 | I12: 5.87 | J12: 6.20 | K12: 7.73 | L12: 9.17 | M12: 12.74 | N12: 14.99 | O12: 17.34 | P12: 6.25 | Q12: 6.25 | R12: 6.25 | S12: 6.25 | T12: 6.51 | U12: 7.66 | V12: 8.33 | W12: 7.81 | X12: 7.81 | Y12: 13.41 | Z12: 15.39 | AA12: 16.06 | AB12: 16.78 | AC12: 17.12
A13: 12 | B13: 6.15 | C13: 7.41 | D13: 9.11 | E13: 13.28 | F13: 19.04 | G13: 20.92 | H13: 21.34 | I13: 5.87 | J13: 7.28 | K13: 8.43 | L13: 10.62 | M13: 13.53 | N13: 15.94 | O13: 18.32 | P13: 6.25 | Q13: 6.25 | R13: 6.25 | S13: 6.25 | T13: 6.74 | U13: 7.97 | V13: 8.71 | W13: 7.81 | X13: 7.88 | Y13: 13.72 | Z13: 16.11 | AA13: 16.74 | AB13: 17.14 | AC13: 17.48
A14: 13 | B14: 6.58 | C14: 7.80 | D14: 9.46 | E14: 14.08 | F14: 20.28 | G14: 21.96 | H14: 23.03 | I14: 6.39 | J14: 7.65 | K14: 8.61 | L14: 10.83 | M14: 13.83 | N14: 16.03 | O14: 19.43 | P14: 6.25 | Q14: 6.25 | R14: 6.25 | S14: 6.34 | T14: 6.95 | U14: 8.46 | V14: 9.11 | W14: 7.81 | X14: 7.96 | Y14: 14.03 | Z14: 16.47 | AA14: 16.82 | AB14: 18.66 | AC14: 19.03
A15: 14 | B15: 6.91 | C15: 8.21 | D15: 10.08 | E15: 14.88 | F15: 21.52 | G15: 23.11 | H15: 24.07 | I15: 6.46 | J15: 7.76 | K15: 9.35 | L15: 11.47 | M15: 14.54 | N15: 16.85 | O15: 20.45 | P15: 6.25 | Q15: 6.25 | R15: 6.25 | S15: 6.50 | T15: 7.35 | U15: 9.06 | V15: 9.91 | W15: 7.81 | X15: 8.06 | Y15: 14.64 | Z15: 16.50 | AA15: 16.83 | AB15: 18.81 | AC15: 19.19
A16: 15 | B16: 7.17 | C16: 8.41 | D16: 10.58 | E16: 15.46 | F16: 22.66 | G16: 24.13 | H16: 25.16 | I16: 6.50 | J16: 8.24 | K16: 9.76 | L16: 11.97 | M16: 15.32 | N16: 18.41 | O16: 21.60 | P16: 6.25 | Q16: 6.25 | R16: 6.25 | S16: 6.73 | T16: 7.76 | U16: 9.34 | V16: 10.31 | W16: 7.81 | X16: 8.10 | Y16: 14.90 | Z16: 16.61 | AA16: 16.94 | AB16: 18.91 | AC16: 19.29
A17: 16 | B17: 7.35 | C17: 8.69 | D17: 11.04 | E17: 15.96 | F17: 23.65 | G17: 25.37 | H17: 26.22 | I17: 6.89 | J17: 8.50 | K17: 10.10 | L17: 12.83 | M17: 15.96 | N17: 19.38 | O17: 22.55 | P17: 6.25 | Q17: 6.25 | R17: 6.25 | S17: 6.85 | T17: 8.01 | U17: 9.84 | V17: 10.82 | W17: 7.81 | X17: 9.08 | Y17: 15.95 | Z17: 18.68 | AA17: 19.05 | AB17: 20.82 | AC17: 21.23
A18: 17 | B18: 7.56 | C18: 8.95 | D18: 11.51 | E18: 16.72 | F18: 24.72 | G18: 26.72 | H18: 27.44 | I18: 6.94 | J18: 8.77 | K18: 10.52 | L18: 12.96 | M18: 16.61 | N18: 19.47 | O18: 23.57 | P18: 6.25 | Q18: 6.25 | R18: 6.25 | S18: 7.04 | T18: 8.35 | U18: 10.34 | V18: 10.83 | W18: 7.81 | X18: 9.18 | Y18: 16.84 | Z18: 18.89 | AA18: 19.27 | AB18: 21.01 | AC18: 21.43
A19: 18 | B19: 7.82 | C19: 9.24 | D19: 11.93 | E19: 17.31 | F19: 25.74 | G19: 27.90 | H19: 28.48 | I19: 7.57 | J19: 9.05 | K19: 10.92 | L19: 13.44 | M19: 17.20 | N19: 21.26 | O19: 24.37 | P19: 6.25 | Q19: 6.25 | R19: 6.25 | S19: 7.37 | T19: 8.79 | U19: 10.65 | V19: 11.67 | W19: 7.81 | X19: 9.23 | Y19: 16.93 | Z19: 18.91 | AA19: 19.29 | AB19: 21.03 | AC19: 21.45
A20: 19 | B20: 8.12 | C20: 9.49 | D20: 12.29 | E20: 18.01 | F20: 26.68 | G20: 29.18 | H20: 30.02 | I20: 7.76 | J20: 9.31 | K20: 11.30 | L20: 13.93 | M20: 17.78 | N20: 21.85 | O20: 25.25 | P20: 6.25 | Q20: 6.34 | R20: 6.49 | S20: 7.73 | T20: 9.05 | U20: 10.97 | V20: 12.23 | W20: 7.81 | X20: 9.25 | Y20: 16.96 | Z20: 18.93 | AA20: 19.31 | AB20: 21.05 | AC20: 21.47
A21: 20 | B21: 8.41 | C21: 9.91 | D21: 12.76 | E21: 18.85 | F21: 27.63 | G21: 30.19 | H21: 31.13 | I21: 7.81 | J21: 9.43 | K21: 11.52 | L21: 14.51 | M21: 18.45 | N21: 21.92 | O21: 26.33 | P21: 6.25 | Q21: 6.39 | R21: 6.53 | S21: 8.03 | T21: 9.35 | U21: 11.38 | V21: 12.68 | W21: 7.81 | X21: 9.28 | Y21: 17.04 | Z21: 18.96 | AA21: 19.37 | AB21: 21.11 | AC21: 21.58
A22: 21 | B22: 8.80 | C22: 10.30 | D22: 13.23 | E22: 19.48 | F22: 27.73 | G22: 31.23 | H22: 31.88 | I22: 8.03 | J22: 9.74 | K22: 11.90 | L22: 14.57 | M22: 19.32 | N22: 23.36 | O22: 27.19 | P22: 6.25 | Q22: 6.64 | R22: 6.87 | S22: 8.12 | T22: 9.65 | U22: 11.70 | V22: 13.07 | W22: 7.81 | X22: 9.71 | Y22: 18.59 | Z22: 19.70 | AA22: 20.55 | AB22: 22.32 | AC22: 23.69
A23: 22 | B23: 9.07 | C23: 10.78 | D23: 13.61 | E23: 20.03 | F23: 29.55 | G23: 32.42 | H23: 33.12 | I23: 8.61 | J23: 10.34 | K23: 12.42 | L23: 15.49 | M23: 19.99 | N23: 23.50 | O23: 28.21 | P23: 6.25 | Q23: 6.71 | R23: 7.06 | S23: 8.35 | T23: 10.04 | U23: 12.13 | V23: 13.64 | W23: 7.81 | X23: 10.25 | Y23: 19.06 | Z23: 20.27 | AA23: 20.70 | AB23: 23.42 | AC23: 24.50
A24: 23 | B24: 9.29 | C24: 11.03 | D24: 14.09 | E24: 20.61 | F24: 30.61 | G24: 33.49 | H24: 34.26 | I24: 8.94 | J24: 10.57 | K24: 13.25 | L24: 15.93 | M24: 20.82 | N24: 25.46 | O24: 28.46 | P24: 6.25 | Q24: 6.83 | R24: 7.22 | S24: 8.50 | T24: 10.42 | U24: 12.42 | V24: 14.18 | W24: 7.81 | X24: 10.30 | Y24: 19.59 | Z24: 21.24 | AA24: 22.37 | AB24: 24.70 | AC24: 25.20
A25: 24 | B25: 9.50 | C25: 11.47 | D25: 14.54 | E25: 21.41 | F25: 31.74 | G25: 33.94 | H25: 34.62 | I25: 8.98 | J25: 11.24 | K25: 13.58 | L25: 16.53 | M25: 21.51 | N25: 25.65 | O25: 28.60 | P25: 6.25 | Q25: 7.11 | R25: 7.59 | S25: 8.96 | T25: 10.91 | U25: 12.84 | V25: 14.99 | W25: 7.81 | X25: 10.35 | Y25: 19.87 | Z25: 22.09 | AA25: 22.53 | AB25: 25.20 | AC25: 25.71
A26: 25 | B26: 9.81 | C26: 11.79 | D26: 14.81 | E26: 22.14 | F26: 32.77 | G26: 36.02 | H26: 37.52 | I26: 9.03 | J26: 11.31 | K26: 14.03 | L26: 17.11 | M26: 22.11 | N26: 27.22 | O26: 31.14 | P26: 6.25 | Q26: 7.14 | R26: 7.62 | S26: 9.13 | T26: 11.23 | U26: 13.55 | V26: 15.45 | W26: 7.81 | X26: 10.38 | Y26: 20.54 | Z26: 22.18 | AA26: 22.97 | AB26: 25.27 | AC26: 25.77
A27: 26 | B27: 10.11 | C27: 12.11 | D27: 15.37 | E27: 22.87 | F27: 33.88 | G27: 37.25 | H27: 38.56 | I27: 9.86 | J27: 11.87 | K27: 14.49 | L27: 17.66 | M27: 22.79 | N27: 28.16 | O27: 32.08 | P27: 6.40 | Q27: 7.38 | R27: 7.94 | S27: 9.50 | T27: 11.64 | U27: 14.10 | V27: 16.09 | W27: 7.86 | X27: 11.21 | Y27: 21.73 | Z27: 23.71 | AA27: 24.79 | AB27: 25.90 | AC27: 27.05
A28: 27 | B28: 10.43 | C28: 12.47 | D28: 15.75 | E28: 23.68 | F28: 35.02 | G28: 38.51 | H28: 39.77 | I28: 10.18 | J28: 12.22 | K28: 15.04 | L28: 18.61 | M28: 23.39 | N28: 29.15 | O28: 33.07 | P28: 6.58 | Q28: 7.56 | R28: 8.10 | S28: 9.66 | T28: 12.11 | U28: 14.36 | V28: 16.36 | W28: 7.91 | X28: 11.29 | Y28: 22.27 | Z28: 23.86 | AA28: 25.40 | AB28: 26.53 | AC28: 28.26
A29: 28 | B29: 10.77 | C29: 12.88 | D29: 16.12 | E29: 24.24 | F29: 35.92 | G29: 39.50 | H29: 40.73 | I29: 10.49 | J29: 12.28 | K29: 15.41 | L29: 18.71 | M29: 25.50 | N29: 30.04 | O29: 34.14 | P29: 6.74 | Q29: 7.74 | R29: 8.48 | S29: 10.23 | T29: 12.70 | U29: 15.00 | V29: 16.99 | W29: 8.07 | X29: 11.34 | Y29: 22.86 | Z29: 24.56 | AA29: 25.46 | AB29: 27.12 | AC29: 28.96
A30: 29 | B30: 11.04 | C30: 13.12 | D30: 16.60 | E30: 24.81 | F30: 36.89 | G30: 40.49 | H30: 41.94 | I30: 10.53 | J30: 12.57 | K30: 15.86 | L30: 19.20 | M30: 26.26 | N30: 30.93 | O30: 35.21 | P30: 6.75 | Q30: 7.89 | R30: 8.55 | S30: 10.23 | T30: 13.06 | U30: 15.34 | V30: 17.44 | W30: 8.12 | X30: 11.39 | Y30: 23.38 | Z30: 24.64 | AA30: 25.48 | AB30: 27.90 | AC30: 29.12
A31: 30 | B31: 11.09 | C31: 13.47 | D31: 17.17 | E31: 25.63 | F31: 37.90 | G31: 41.58 | H31: 43.01 | I31: 10.57 | J31: 12.92 | K31: 15.90 | L31: 19.80 | M31: 27.10 | N31: 31.02 | O31: 36.21 | P31: 6.82 | Q31: 8.08 | R31: 8.88 | S31: 10.63 | T31: 13.27 | U31: 15.42 | V31: 18.17 | W31: 8.16 | X31: 11.41 | Y31: 23.43 | Z31: 24.85 | AA31: 25.60 | AB31: 28.02 | AC31: 29.18
A32: 31 | B32: 11.13 | C32: 13.93 | D32: 17.64 | E32: 26.20 | F32: 38.76 | G32: 42.49 | H32: 44.15 | I32: 10.92 | J32: 13.66 | K32: 16.37 | L32: 20.70 | M32: 28.48 | N32: 31.83 | O32: 37.20 | P32: 7.11 | Q32: 8.25 | R32: 9.06 | S32: 10.77 | T32: 13.66 | U32: 16.00 | V32: 18.74 | W32: 8.46 | X32: 11.73 | Y32: 24.43 | Z32: 25.96 | AA32: 27.78 | AB32: 28.98 | AC32: 30.26
A33: 32 | B33: 11.18 | C33: 14.23 | D33: 18.14 | E33: 26.83 | F33: 39.90 | G33: 43.67 | H33: 45.22 | I33: 10.96 | J33: 13.74 | K33: 16.84 | L33: 20.78 | M33: 28.62 | N33: 32.07 | O33: 37.33 | P33: 7.12 | Q33: 8.26 | R33: 9.06 | S33: 10.77 | T33: 13.66 | U33: 16.00 | V33: 18.95 | W33: 8.70 | X33: 12.01 | Y33: 24.96 | Z33: 26.07 | AA33: 28.00 | AB33: 29.11 | AC33: 30.75
A34: 33 | B34: 12.10 | C34: 14.61 | D34: 18.64 | E34: 27.40 | F34: 40.97 | G34: 44.68 | H34: 46.37 | I34: 11.58 | J34: 14.03 | K34: 17.52 | L34: 21.36 | M34: 29.45 | N34: 32.90 | O34: 37.47 | P34: 7.16 | Q34: 8.38 | R34: 9.47 | S34: 11.28 | T34: 14.52 | U34: 16.53 | V34: 19.46 | W34: 8.92 | X34: 12.69 | Y34: 25.36 | Z34: 27.81 | AA34: 28.50 | AB34: 30.83 | AC34: 31.97
A35: 34 | B35: 12.49 | C35: 14.88 | D35: 19.03 | E35: 28.37 | F35: 42.20 | G35: 45.78 | H35: 47.52 | I35: 11.81 | J35: 14.07 | K35: 17.59 | L35: 21.87 | M35: 29.93 | N35: 33.66 | O35: 40.31 | P35: 7.20 | Q35: 8.57 | R35: 9.77 | S35: 11.67 | T35: 14.52 | U35: 17.02 | V35: 20.40 | W35: 9.10 | X35: 12.76 | Y35: 25.90 | Z35: 27.99 | AA35: 28.55 | AB35: 31.48 | AC35: 32.12
A36: 35 | B36: 12.74 | C36: 15.33 | D36: 19.44 | E36: 28.93 | F36: 43.48 | G36: 46.79 | H36: 47.72 | I36: 12.04 | J36: 14.69 | K36: 18.10 | L36: 22.42 | M36: 29.98 | N36: 34.52 | O36: 40.60 | P36: 7.34 | Q36: 9.02 | R36: 10.09 | S36: 11.96 | T36: 14.77 | U36: 17.46 | V36: 20.54 | W36: 9.30 | X36: 12.80 | Y36: 25.96 | Z36: 28.02 | AA36: 28.60 | AB36: 31.78 | AC36: 32.41
A37: 36 | B37: 12.94 | C37: 15.66 | D37: 19.85 | E37: 29.52 | F37: 44.65 | G37: 48.00 | H37: 48.95 | I37: 12.38 | J37: 15.02 | K37: 18.78 | L37: 22.50 | M37: 30.10 | N37: 35.22 | O37: 42.37 | P37: 7.44 | Q37: 9.03 | R37: 10.17 | S37: 12.25 | T37: 15.39 | U37: 18.05 | V37: 21.35 | W37: 9.69 | X37: 13.05 | Y37: 26.98 | Z37: 28.59 | AA37: 29.60 | AB37: 32.24 | AC37: 33.10
A38: 37 | B38: 13.17 | C38: 15.89 | D38: 20.33 | E38: 30.29 | F38: 45.86 | G38: 49.70 | H38: 51.25 | I38: 12.44 | J38: 15.13 | K38: 18.84 | L38: 23.46 | M38: 32.36 | N38: 35.93 | O38: 42.55 | P38: 7.55 | Q38: 9.14 | R38: 10.28 | S38: 12.52 | T38: 15.46 | U38: 18.64 | V38: 21.56 | W38: 9.72 | X38: 13.92 | Y38: 27.61 | Z38: 30.30 | AA38: 31.04 | AB38: 33.30 | AC38: 34.22
... A100: 99 | B100: 29.48 | C100: 35.02 | D100: 44.00 | E100: 66.01 | F100: 108.63 | G100: 113.84 | H100: 117.41 | I100: 28.54 | J100: 34.33 | K100: 43.13 | L100: 55.70 | M100: 77.80 | N100: 87.57 | O100: 106.02 | P100: 21.96 | Q100: 21.98 | R100: 24.11 | S100: 25.99 | T100: 30.17 | U100: 33.70 | V100: 37.14 | W100: 22.97 | X100: 32.15 | Y100: 58.29 | Z100: 67.03 | AA100: 68.66 | AB100: 78.89 | AC100: 80.46

Sheet FedEx Total Spend
A1: Wgt | B1: 2Day*2 | C1: 2Day*3 | D1: 2Day*4 | E1: 2Day*5 | F1: 2Day*6 | G1: 2Day*7 | H1: 2Day*8 | I1: 3Day*2 | J1: 3Day*3 | K1: 3Day*4 | L1: 3Day*5 | M1: 3Day*6 | N1: 3Day*7 | O1: 3Day*8 | P1: Ground*2 | Q1: Ground*3 | R1: Ground*4 | S1: Ground*5 | T1: Ground*6 | U1: Ground*7 | V1: Ground*8 | W1: Next Day AM*2 | X1: Next Day AM*3 | Y1: Next Day AM*4 | Z1: Next Day AM*5 | AA1: Next Day AM*6 | AB1: Next Day AM*7 | AC1: Next Day AM*8
A2: 1 | B2: =SUM('TOTAL VOLUME'!B2*'FedEx Rates'!B2) -> 348.27 | C2: =SUM('TOTAL VOLUME'!C2*'FedEx Rates'!C2) -> 109.98 | D2: =SUM('TOTAL VOLUME'!D2*'FedEx Rates'!D2) -> 238.29 | E2: =SUM('TOTAL VOLUME'!E2*'FedEx Rates'!E2) -> 238.29 | F2: =SUM('TOTAL VOLUME'!F2*'FedEx Rates'!F2) -> 177.19 | G2: =SUM('TOTAL VOLUME'!G2*'FedEx Rates'!G2) -> 54.99 | H2: =SUM('TOTAL VOLUME'!H2*'FedEx Rates'!H2) -> 207.74 | I2: =SUM('TOTAL VOLUME'!I2*'FedEx Rates'!I2) -> 52.83 | ... AC2: =SUM('TOTAL VOLUME'!AC2*'FedEx Rates'!AC2) -> 2096.58
A3: 2 | B3: =SUM('TOTAL VOLUME'!B3*'FedEx Rates'!B3) -> 262.73 | C3: =SUM('TOTAL VOLUME'!C3*'FedEx Rates'!C3) -> 122.2 | D3: =SUM('TOTAL VOLUME'!D3*'FedEx Rates'!D3) -> 152.75 | E3: =SUM('TOTAL VOLUME'!E3*'FedEx Rates'!E3) -> 183.3 | F3: =SUM('TOTAL VOLUME'!F3*'FedEx Rates'!F3) -> 146.64 | G3: =SUM('TOTAL VOLUME'!G3*'FedEx Rates'!G3) -> 103.87 | H3: =SUM('TOTAL VOLUME'!H3*'FedEx Rates'!H3) -> 293.28 | I3: =SUM('TOTAL VOLUME'!I3*'FedEx Rates'!I3) -> 11.74 | ... AC3: =SUM('TOTAL VOLUME'!AC3*'FedEx Rates'!AC3) -> 2531.29
A4: 3 | B4: =SUM('TOTAL VOLUME'!B4*'FedEx Rates'!B4) -> 354.38 | C4: =SUM('TOTAL VOLUME'!C4*'FedEx Rates'!C4) -> 103.87 | D4: =SUM('TOTAL VOLUME'!D4*'FedEx Rates'!D4) -> 79.43 | E4: =SUM('TOTAL VOLUME'!E4*'FedEx Rates'!E4) -> 109.98 | F4: =SUM('TOTAL VOLUME'!F4*'FedEx Rates'!F4) -> 118.35 | G4: =SUM('TOTAL VOLUME'!G4*'FedEx Rates'!G4) -> 203.09 | H4: =SUM('TOTAL VOLUME'!H4*'FedEx Rates'!H4) -> 451.29 | I4: =SUM('TOTAL VOLUME'!I4*'FedEx Rates'!I4) -> 11.74 | ... AC4: =SUM('TOTAL VOLUME'!AC4*'FedEx Rates'!AC4) -> 2942.94
A5: 4 | B5: =SUM('TOTAL VOLUME'!B5*'FedEx Rates'!B5) -> 116.09 | C5: =SUM('TOTAL VOLUME'!C5*'FedEx Rates'!C5) -> 79.43 | D5: =SUM('TOTAL VOLUME'!D5*'FedEx Rates'!D5) -> 73.32 | E5: =SUM('TOTAL VOLUME'!E5*'FedEx Rates'!E5) -> 276.51 | F5: =SUM('TOTAL VOLUME'!F5*'FedEx Rates'!F5) -> 383.04 | G5: =SUM('TOTAL VOLUME'!G5*'FedEx Rates'!G5) -> 403.6 | H5: =SUM('TOTAL VOLUME'!H5*'FedEx Rates'!H5) -> 1739.68 | I5: =SUM('TOTAL VOLUME'!I5*'FedEx Rates'!I5) -> 0 | ... AC5: =SUM('TOTAL VOLUME'!AC5*'FedEx Rates'!AC5) -> 6608
A6: 5 | B6: =SUM('TOTAL VOLUME'!B6*'FedEx Rates'!B6) -> 36.66 | C6: =SUM('TOTAL VOLUME'!C6*'FedEx Rates'!C6) -> 18.33 | D6: =SUM('TOTAL VOLUME'!D6*'FedEx Rates'!D6) -> 18.33 | E6: =SUM('TOTAL VOLUME'!E6*'FedEx Rates'!E6) -> 196.75 | F6: =SUM('TOTAL VOLUME'!F6*'FedEx Rates'!F6) -> 152.85 | G6: =SUM('TOTAL VOLUME'!G6*'FedEx Rates'!G6) -> 146.12 | H6: =SUM('TOTAL VOLUME'!H6*'FedEx Rates'!H6) -> 619.84 | I6: =SUM('TOTAL VOLUME'!I6*'FedEx Rates'!I6) -> 11.74 | ... AC6: =SUM('TOTAL VOLUME'!AC6*'FedEx Rates'!AC6) -> 6265.95
A7: 6 | B7: =SUM('TOTAL VOLUME'!B7*'FedEx Rates'!B7) -> 42.77 | C7: =SUM('TOTAL VOLUME'!C7*'FedEx Rates'!C7) -> 24.44 | D7: =SUM('TOTAL VOLUME'!D7*'FedEx Rates'!D7) -> 36.72 | E7: =SUM('TOTAL VOLUME'!E7*'FedEx Rates'!E7) -> 94.6 | F7: =SUM('TOTAL VOLUME'!F7*'FedEx Rates'!F7) -> 56.6 | G7: =SUM('TOTAL VOLUME'!G7*'FedEx Rates'!G7) -> 49.96 | H7: =SUM('TOTAL VOLUME'!H7*'FedEx Rates'!H7) -> 326.25 | I7: =SUM('TOTAL VOLUME'!I7*'FedEx Rates'!I7) -> 11.74 | ... AC7: =SUM('TOTAL VOLUME'!AC7*'FedEx Rates'!AC7) -> 3154.69
A8: 7 | B8: =SUM('TOTAL VOLUME'!B8*'FedEx Rates'!B8) -> 12.22 | C8: =SUM('TOTAL VOLUME'!C8*'FedEx Rates'!C8) -> 0 | D8: =SUM('TOTAL VOLUME'!D8*'FedEx Rates'!D8) -> 13.26 | E8: =SUM('TOTAL VOLUME'!E8*'FedEx Rates'!E8) -> 206.8 | F8: =SUM('TOTAL VOLUME'!F8*'FedEx Rates'!F8) -> 127.4 | G8: =SUM('TOTAL VOLUME'!G8*'FedEx Rates'!G8) -> 180.18 | H8: =SUM('TOTAL VOLUME'!H8*'FedEx Rates'!H8) -> 532.06 | I8: =SUM('TOTAL VOLUME'!I8*'FedEx Rates'!I8) -> 5.87 | ... AC8: =SUM('TOTAL VOLUME'!AC8*'FedEx Rates'!AC8) -> 3441.54
A9: 8 | B9: =SUM('TOTAL VOLUME'!B9*'FedEx Rates'!B9) -> 18.33 | C9: =SUM('TOTAL VOLUME'!C9*'FedEx Rates'!C9) -> 6.11 | D9: =SUM('TOTAL VOLUME'!D9*'FedEx Rates'!D9) -> 71 | E9: =SUM('TOTAL VOLUME'!E9*'FedEx Rates'!E9) -> 235.75 | F9: =SUM('TOTAL VOLUME'!F9*'FedEx Rates'!F9) -> 239.53 | G9: =SUM('TOTAL VOLUME'!G9*'FedEx Rates'!G9) -> 198.51 | H9: =SUM('TOTAL VOLUME'!H9*'FedEx Rates'!H9) -> 981.46 | I9: =SUM('TOTAL VOLUME'!I9*'FedEx Rates'!I9) -> 29.35 | ... AC9: =SUM('TOTAL VOLUME'!AC9*'FedEx Rates'!AC9) -> 2987.01
A10: 9 | B10: =SUM('TOTAL VOLUME'!B10*'FedEx Rates'!B10) -> 0 | C10: =SUM('TOTAL VOLUME'!C10*'FedEx Rates'!C10) -> 18.72 | D10: =SUM('TOTAL VOLUME'!D10*'FedEx Rates'!D10) -> 145.73 | E10: =SUM('TOTAL VOLUME'!E10*'FedEx Rates'!E10) -> 495 | F10: =SUM('TOTAL VOLUME'!F10*'FedEx Rates'!F10) -> 490.56 | G10: =SUM('TOTAL VOLUME'!G10*'FedEx Rates'!G10) -> 335 | H10: =SUM('TOTAL VOLUME'!H10*'FedEx Rates'!H10) -> 1719.63 | I10: =SUM('TOTAL VOLUME'!I10*'FedEx Rates'!I10) -> 0 | ... AC10: =SUM('TOTAL VOLUME'!AC10*'FedEx Rates'!AC10) -> 4775.1
A11: 10 | B11: =SUM('TOTAL VOLUME'!B11*'FedEx Rates'!B11) -> 12.22 | C11: =SUM('TOTAL VOLUME'!C11*'FedEx Rates'!C11) -> 0 | D11: =SUM('TOTAL VOLUME'!D11*'FedEx Rates'!D11) -> 16.52 | E11: =SUM('TOTAL VOLUME'!E11*'FedEx Rates'!E11) -> 105.75 | F11: =SUM('TOTAL VOLUME'!F11*'FedEx Rates'!F11) -> 163.7 | G11: =SUM('TOTAL VOLUME'!G11*'FedEx Rates'!G11) -> 163.98 | H11: =SUM('TOTAL VOLUME'!H11*'FedEx Rates'!H11) -> 375.8 | I11: =SUM('TOTAL VOLUME'!I11*'FedEx Rates'!I11) -> 11.74 | ... AC11: =SUM('TOTAL VOLUME'!AC11*'FedEx Rates'!AC11) -> 4818
A12: 11 | B12: =SUM('TOTAL VOLUME'!B12*'FedEx Rates'!B12) -> 18.33 | C12: =SUM('TOTAL VOLUME'!C12*'FedEx Rates'!C12) -> 0 | D12: =SUM('TOTAL VOLUME'!D12*'FedEx Rates'!D12) -> 43.2 | E12: =SUM('TOTAL VOLUME'!E12*'FedEx Rates'!E12) -> 226.26 | F12: =SUM('TOTAL VOLUME'!F12*'FedEx Rates'!F12) -> 88.35 | G12: =SUM('TOTAL VOLUME'!G12*'FedEx Rates'!G12) -> 351.54 | H12: =SUM('TOTAL VOLUME'!H12*'FedEx Rates'!H12) -> 427.56 | I12: =SUM('TOTAL VOLUME'!I12*'FedEx Rates'!I12) -> 0 | ... AC12: =SUM('TOTAL VOLUME'!AC12*'FedEx Rates'!AC12) -> 5820.8
A13: 12 | B13: =SUM('TOTAL VOLUME'!B13*'FedEx Rates'!B13) -> 18.45 | C13: =SUM('TOTAL VOLUME'!C13*'FedEx Rates'!C13) -> 37.05 | D13: =SUM('TOTAL VOLUME'!D13*'FedEx Rates'!D13) -> 72.88 | E13: =SUM('TOTAL VOLUME'!E13*'FedEx Rates'!E13) -> 159.36 | F13: =SUM('TOTAL VOLUME'!F13*'FedEx Rates'!F13) -> 304.64 | G13: =SUM('TOTAL VOLUME'!G13*'FedEx Rates'!G13) -> 230.12 | H13: =SUM('TOTAL VOLUME'!H13*'FedEx Rates'!H13) -> 576.18 | I13: =SUM('TOTAL VOLUME'!I13*'FedEx Rates'!I13) -> 5.87 | ... AC13: =SUM('TOTAL VOLUME'!AC13*'FedEx Rates'!AC13) -> 4562.28
... A100: 99 | B100: =SUM('TOTAL VOLUME'!B100*'FedEx Rates'!B100) -> 0 | C100: =SUM('TOTAL VOLUME'!C100*'FedEx Rates'!C100) -> 0 | D100: =SUM('TOTAL VOLUME'!D100*'FedEx Rates'!D100) -> 0 | E100: =SUM('TOTAL VOLUME'!E100*'FedEx Rates'!E100) -> 0 | F100: =SUM('TOTAL VOLUME'!F100*'FedEx Rates'!F100) -> 0 | G100: =SUM('TOTAL VOLUME'!G100*'FedEx Rates'!G100) -> 0 | H100: =SUM('TOTAL VOLUME'!H100*'FedEx Rates'!H100) -> 0 | I100: =SUM('TOTAL VOLUME'!I100*'FedEx Rates'!I100) -> 0 | ... AC100: =SUM('TOTAL VOLUME'!AC100*'FedEx Rates'!AC100) -> 0
B101: =SUM(B2:B100) -> 2219.81 | C101: =SUM(C2:C100) -> 1177.07 | D101: =SUM(D2:D100) -> 2526.29 | E101: =SUM(E2:E100) -> 8536.46 | F101: =SUM(F2:F100) -> 7611.32 | G101: =SUM(G2:G100) -> 6668.54 | H101: =SUM(H2:H100) -> 23506.95 | I101: =SUM(I2:I100) -> 286.48 | ... AC101: =SUM(AC2:AC100) -> 177870.38
B103: Total FedEx | F103: Difference UPS-FEDEX | P103: =SUM(P101:V101) -> 1241833.3
B104: =SUM(B101:AC101) -> 1824642.2 | F104: =SUM('UPS TOTAL SPEND'!B103-'FedEx Total Spend'!B104) -> 938361.37
B106: Total UPS
B107: ='UPS TOTAL SPEND'!B103 -> 2763003.6 | F107: =SUM(F104/B107) -> 0.33961641

Sheet Side by Side Amount
A2: Wgt | B2: 2Day*2 | C2: 2Day*3 | D2: 2Day*4 | E2: 2Day*5 | F2: 2Day*6 | G2: 2Day*7 | H2: 2Day*8 | I2: 3Day*2 | J2: 3Day*3 | K2: 3Day*4 | L2: 3Day*5 | M2: 3Day*6 | N2: 3Day*7 | O2: 3Day*8 | P2: Ground*2 | Q2: Ground*3 | R2: Ground*4 | S2: Ground*5 | T2: Ground*6 | U2: Ground*7 | V2: Ground*8 | W2: Next Day AM*2 | X2: Next Day AM*3 | Y2: Next Day AM*4 | Z2: Next Day AM*5 | AA2: Next Day AM*6 | AB2: Next Day AM*7 | AC2: Next Day AM*8
A3: 1 | B3: =SUM('UPS RATES'!B3-'FedEx Rates'!B2) -> 1.95 | C3: =SUM('UPS RATES'!C3-'FedEx Rates'!C2) -> 1.95 | D3: =SUM('UPS RATES'!D3-'FedEx Rates'!D2) -> 1.95 | E3: =SUM('UPS RATES'!E3-'FedEx Rates'!E2) -> 1.95 | F3: =SUM('UPS RATES'!F3-'FedEx Rates'!F2) -> 1.98 | G3: =SUM('UPS RATES'!G3-'FedEx Rates'!G2) -> 2.52 | H3: =SUM('UPS RATES'!H3-'FedEx Rates'!H2) -> 2.69 | I3: =SUM('UPS RATES'!I3-'FedEx Rates'!I2) -> 2.37 | ... AC3: =SUM('UPS RATES'!AC3-'FedEx Rates'!AC2) -> 9.27
A4: 2 | B4: =SUM('UPS RATES'!B4-'FedEx Rates'!B3) -> 1.95 | C4: =SUM('UPS RATES'!C4-'FedEx Rates'!C3) -> 1.95 | D4: =SUM('UPS RATES'!D4-'FedEx Rates'!D3) -> 1.95 | E4: =SUM('UPS RATES'!E4-'FedEx Rates'!E3) -> 1.95 | F4: =SUM('UPS RATES'!F4-'FedEx Rates'!F3) -> 2.99 | G4: =SUM('UPS RATES'!G4-'FedEx Rates'!G3) -> 3.98 | H4: =SUM('UPS RATES'!H4-'FedEx Rates'!H3) -> 4.51 | I4: =SUM('UPS RATES'!I4-'FedEx Rates'!I3) -> 2.37 | ... AC4: =SUM('UPS RATES'!AC4-'FedEx Rates'!AC3) -> 10.36
A5: 3 | B5: =SUM('UPS RATES'!B5-'FedEx Rates'!B4) -> 1.95 | C5: =SUM('UPS RATES'!C5-'FedEx Rates'!C4) -> 1.95 | D5: =SUM('UPS RATES'!D5-'FedEx Rates'!D4) -> 1.95 | E5: =SUM('UPS RATES'!E5-'FedEx Rates'!E4) -> 1.95 | F5: =SUM('UPS RATES'!F5-'FedEx Rates'!F4) -> 2.57 | G5: =SUM('UPS RATES'!G5-'FedEx Rates'!G4) -> 2.87 | H5: =SUM('UPS RATES'!H5-'FedEx Rates'!H4) -> 2.97 | I5: =SUM('UPS RATES'!I5-'FedEx Rates'!I4) -> 2.37 | ... AC5: =SUM('UPS RATES'!AC5-'FedEx Rates'!AC4) -> 11.32
A6: 4 | B6: =SUM('UPS RATES'!B6-'FedEx Rates'!B5) -> 1.95 | C6: =SUM('UPS RATES'!C6-'FedEx Rates'!C5) -> 1.95 | D6: =SUM('UPS RATES'!D6-'FedEx Rates'!D5) -> 1.95 | E6: =SUM('UPS RATES'!E6-'FedEx Rates'!E5) -> 2.24 | F6: =SUM('UPS RATES'!F6-'FedEx Rates'!F5) -> 2.94 | G6: =SUM('UPS RATES'!G6-'FedEx Rates'!G5) -> 3.24 | H6: =SUM('UPS RATES'!H6-'FedEx Rates'!H5) -> 3.36 | I6: =SUM('UPS RATES'!I6-'FedEx Rates'!I5) -> 2.37 | ... AC6: =SUM('UPS RATES'!AC6-'FedEx Rates'!AC5) -> 12.32
A7: 5 | B7: =SUM('UPS RATES'!B7-'FedEx Rates'!B6) -> 1.95 | C7: =SUM('UPS RATES'!C7-'FedEx Rates'!C6) -> 1.95 | D7: =SUM('UPS RATES'!D7-'FedEx Rates'!D6) -> 1.95 | E7: =SUM('UPS RATES'!E7-'FedEx Rates'!E6) -> 2.47 | F7: =SUM('UPS RATES'!F7-'FedEx Rates'!F6) -> 3.28 | G7: =SUM('UPS RATES'!G7-'FedEx Rates'!G6) -> 3.58 | H7: =SUM('UPS RATES'!H7-'FedEx Rates'!H6) -> 3.79 | I7: =SUM('UPS RATES'!I7-'FedEx Rates'!I6) -> 2.37 | ... AC7: =SUM('UPS RATES'!AC7-'FedEx Rates'!AC6) -> 12.33
A8: 6 | B8: =SUM('UPS RATES'!B8-'FedEx Rates'!B7) -> 1.95 | C8: =SUM('UPS RATES'!C8-'FedEx Rates'!C7) -> 1.95 | D8: =SUM('UPS RATES'!D8-'FedEx Rates'!D7) -> 2 | E8: =SUM('UPS RATES'!E8-'FedEx Rates'!E7) -> 2.69 | F8: =SUM('UPS RATES'!F8-'FedEx Rates'!F7) -> 3.62 | G8: =SUM('UPS RATES'!G8-'FedEx Rates'!G7) -> 3.98 | H8: =SUM('UPS RATES'!H8-'FedEx Rates'!H7) -> 4.15 | I8: =SUM('UPS RATES'!I8-'FedEx Rates'!I7) -> 2.37 | ... AC8: =SUM('UPS RATES'!AC8-'FedEx Rates'!AC7) -> 14.4
A9: 7 | B9: =SUM('UPS RATES'!B9-'FedEx Rates'!B8) -> 1.95 | C9: =SUM('UPS RATES'!C9-'FedEx Rates'!C8) -> 1.95 | D9: =SUM('UPS RATES'!D9-'FedEx Rates'!D8) -> 2.17 | E9: =SUM('UPS RATES'!E9-'FedEx Rates'!E8) -> 2.94 | F9: =SUM('UPS RATES'!F9-'FedEx Rates'!F8) -> 4.07 | G9: =SUM('UPS RATES'!G9-'FedEx Rates'!G8) -> 4.35 | H9: =SUM('UPS RATES'!H9-'FedEx Rates'!H8) -> 4.53 | I9: =SUM('UPS RATES'!I9-'FedEx Rates'!I8) -> 2.37 | ... AC9: =SUM('UPS RATES'!AC9-'FedEx Rates'!AC8) -> 15.38
A10: 8 | B10: =SUM('UPS RATES'!B10-'FedEx Rates'!B9) -> 1.95 | C10: =SUM('UPS RATES'!C10-'FedEx Rates'!C9) -> 1.95 | D10: =SUM('UPS RATES'!D10-'FedEx Rates'!D9) -> 2.31 | E10: =SUM('UPS RATES'!E10-'FedEx Rates'!E9) -> 3.21 | F10: =SUM('UPS RATES'!F10-'FedEx Rates'!F9) -> 4.47 | G10: =SUM('UPS RATES'!G10-'FedEx Rates'!G9) -> 4.79 | H10: =SUM('UPS RATES'!H10-'FedEx Rates'!H9) -> 4.99 | I10: =SUM('UPS RATES'!I10-'FedEx Rates'!I9) -> 2.37 | ... AC10: =SUM('UPS RATES'!AC10-'FedEx Rates'!AC9) -> 15.85
A11: 9 | B11: =SUM('UPS RATES'!B11-'FedEx Rates'!B10) -> 1.95 | C11: =SUM('UPS RATES'!C11-'FedEx Rates'!C10) -> 1.96 | D11: =SUM('UPS RATES'!D11-'FedEx Rates'!D10) -> 2.5 | E11: =SUM('UPS RATES'!E11-'FedEx Rates'!E10) -> 3.45 | F11: =SUM('UPS RATES'!F11-'FedEx Rates'!F10) -> 4.83 | G11: =SUM('UPS RATES'!G11-'FedEx Rates'!G10) -> 5.25 | H11: =SUM('UPS RATES'!H11-'FedEx Rates'!H10) -> 5.45 | I11: =SUM('UPS RATES'!I11-'FedEx Rates'!I10) -> 2.37 | ... AC11: =SUM('UPS RATES'!AC11-'FedEx Rates'!AC10) -> 15.91
A12: 10 | B12: =SUM('UPS RATES'!B12-'FedEx Rates'!B11) -> 1.95 | C12: =SUM('UPS RATES'!C12-'FedEx Rates'!C11) -> 2.08 | D12: =SUM('UPS RATES'!D12-'FedEx Rates'!D11) -> 2.69 | E12: =SUM('UPS RATES'!E12-'FedEx Rates'!E11) -> 3.69 | F12: =SUM('UPS RATES'!F12-'FedEx Rates'!F11) -> 5.23 | G12: =SUM('UPS RATES'!G12-'FedEx Rates'!G11) -> 5.71 | H12: =SUM('UPS RATES'!H12-'FedEx Rates'!H11) -> 5.92 | I12: =SUM('UPS RATES'!I12-'FedEx Rates'!I11) -> 2.37 | ... AC12: =SUM('UPS RATES'!AC12-'FedEx Rates'!AC11) -> 16.04
A13: 11 | B13: =SUM('UPS RATES'!B13-'FedEx Rates'!B12) -> 1.95 | C13: =SUM('UPS RATES'!C13-'FedEx Rates'!C12) -> 2.21 | D13: =SUM('UPS RATES'!D13-'FedEx Rates'!D12) -> 2.82 | E13: =SUM('UPS RATES'!E13-'FedEx Rates'!E12) -> 3.94 | F13: =SUM('UPS RATES'!F13-'FedEx Rates'!F12) -> 5.6 | G13: =SUM('UPS RATES'!G13-'FedEx Rates'!G12) -> 6.16 | H13: =SUM('UPS RATES'!H13-'FedEx Rates'!H12) -> 6.39 | I13: =SUM('UPS RATES'!I13-'FedEx Rates'!I12) -> 2.43 | ... AC13: =SUM('UPS RATES'!AC13-'FedEx Rates'!AC12) -> 18.82
A14: 12 | B14: =SUM('UPS RATES'!B14-'FedEx Rates'!B13) -> 1.93 | C14: =SUM('UPS RATES'!C14-'FedEx Rates'!C13) -> 2.35 | D14: =SUM('UPS RATES'!D14-'FedEx Rates'!D13) -> 2.98 | E14: =SUM('UPS RATES'!E14-'FedEx Rates'!E13) -> 4.16 | F14: =SUM('UPS RATES'!F14-'FedEx Rates'!F13) -> 6.03 | G14: =SUM('UPS RATES'!G14-'FedEx Rates'!G13) -> 6.63 | H14: =SUM('UPS RATES'!H14-'FedEx Rates'!H13) -> 6.97 | I14: =SUM('UPS RATES'!I14-'FedEx Rates'!I13) -> 2.88 | ... AC14: =SUM('UPS RATES'!AC14-'FedEx Rates'!AC13) -> 19.22
... A101: 99 | B101: =SUM('UPS RATES'!B101-'FedEx Rates'!B100) -> 10.22 | C101: =SUM('UPS RATES'!C101-'FedEx Rates'!C100) -> 10.98 | D101: =SUM('UPS RATES'!D101-'FedEx Rates'!D100) -> 13.8 | E101: =SUM('UPS RATES'!E101-'FedEx Rates'!E100) -> 20.71 | F101: =SUM('UPS RATES'!F101-'FedEx Rates'!F100) -> 34.09 | G101: =SUM('UPS RATES'!G101-'FedEx Rates'!G100) -> 35.71 | H101: =SUM('UPS RATES'!H101-'FedEx Rates'!H100) -> 38.38 | I101: =SUM('UPS RATES'!I101-'FedEx Rates'!I100) -> 12.25 | ... AC101: =SUM('UPS RATES'!AC101-'FedEx Rates'!AC100) -> 87.74

Sheet Side by Side Percentage
A2: Wgt | B2: 2Day*2 | C2: 2Day*3 | D2: 2Day*4 | E2: 2Day*5 | F2: 2Day*6 | G2: 2Day*7 | H2: 2Day*8 | I2: 3Day*2 | J2: 3Day*3 | K2: 3Day*4 | L2: 3Day*5 | M2: 3Day*6 | N2: 3Day*7 | O2: 3Day*8 | P2: Ground*2 | Q2: Ground*3 | R2: Ground*4 | S2: Ground*5 | T2: Ground*6 | U2: Ground*7 | V2: Ground*8 | W2: Next Day AM*2 | X2: Next Day AM*3 | Y2: Next Day AM*4 | Z2: Next Day AM*5 | AA2: Next Day AM*6 | AB2: Next Day AM*7 | AC2: Next Day AM*8
A3: 1 | B3: =SUM('UPS RATES'!B3-'FedEx Rates'!B2)/('UPS RATES'!B3) -> 0.24193548 | C3: =SUM('UPS RATES'!C3-'FedEx Rates'!C2)/('UPS RATES'!C3) -> 0.24193548 | D3: =SUM('UPS RATES'!D3-'FedEx Rates'!D2)/('UPS RATES'!D3) -> 0.24193548 | E3: =SUM('UPS RATES'!E3-'FedEx Rates'!E2)/('UPS RATES'!E3) -> 0.24193548 | F3: =SUM('UPS RATES'!F3-'FedEx Rates'!F2)/('UPS RATES'!F3) -> 0.2447466 | G3: =SUM('UPS RATES'!G3-'FedEx Rates'!G2)/('UPS RATES'!G3) -> 0.29200463 | H3: =SUM('UPS RATES'!H3-'FedEx Rates'!H2)/('UPS RATES'!H3) -> 0.30568182 | I3: =SUM('UPS RATES'!I3-'FedEx Rates'!I2)/('UPS RATES'!I3) -> 0.28762136 | ... AC3: =SUM('UPS RATES'!AC3-'FedEx Rates'!AC2)/('UPS RATES'!AC3) -> 0.52402487
A4: 2 | B4: =SUM('UPS RATES'!B4-'FedEx Rates'!B3)/('UPS RATES'!B4) -> 0.24193548 | C4: =SUM('UPS RATES'!C4-'FedEx Rates'!C3)/('UPS RATES'!C4) -> 0.24193548 | D4: =SUM('UPS RATES'!D4-'FedEx Rates'!D3)/('UPS RATES'!D4) -> 0.24193548 | E4: =SUM('UPS RATES'!E4-'FedEx Rates'!E3)/('UPS RATES'!E4) -> 0.24193548 | F4: =SUM('UPS RATES'!F4-'FedEx Rates'!F3)/('UPS RATES'!F4) -> 0.32857143 | G4: =SUM('UPS RATES'!G4-'FedEx Rates'!G3)/('UPS RATES'!G4) -> 0.39444995 | H4: =SUM('UPS RATES'!H4-'FedEx Rates'!H3)/('UPS RATES'!H4) -> 0.42467043 | I4: =SUM('UPS RATES'!I4-'FedEx Rates'!I3)/('UPS RATES'!I4) -> 0.28762136 | ... AC4: =SUM('UPS RATES'!AC4-'FedEx Rates'!AC3)/('UPS RATES'!AC4) -> 0.5240263
A5: 3 | B5: =SUM('UPS RATES'!B5-'FedEx Rates'!B4)/('UPS RATES'!B5) -> 0.24193548 | C5: =SUM('UPS RATES'!C5-'FedEx Rates'!C4)/('UPS RATES'!C5) -> 0.24193548 | D5: =SUM('UPS RATES'!D5-'FedEx Rates'!D4)/('UPS RATES'!D5) -> 0.24193548 | E5: =SUM('UPS RATES'!E5-'FedEx Rates'!E4)/('UPS RATES'!E5) -> 0.24193548 | F5: =SUM('UPS RATES'!F5-'FedEx Rates'!F4)/('UPS RATES'!F5) -> 0.2456979 | G5: =SUM('UPS RATES'!G5-'FedEx Rates'!G4)/('UPS RATES'!G5) -> 0.24529915 | H5: =SUM('UPS RATES'!H5-'FedEx Rates'!H4)/('UPS RATES'!H5) -> 0.24384236 | I5: =SUM('UPS RATES'!I5-'FedEx Rates'!I4)/('UPS RATES'!I5) -> 0.28762136 | ... AC5: =SUM('UPS RATES'!AC5-'FedEx Rates'!AC4)/('UPS RATES'!AC5) -> 0.52383156
A6: 4 | B6: =SUM('UPS RATES'!B6-'FedEx Rates'!B5)/('UPS RATES'!B6) -> 0.24193548 | C6: =SUM('UPS RATES'!C6-'FedEx Rates'!C5)/('UPS RATES'!C6) -> 0.24193548 | D6: =SUM('UPS RATES'!D6-'FedEx Rates'!D5)/('UPS RATES'!D6) -> 0.24193548 | E6: =SUM('UPS RATES'!E6-'FedEx Rates'!E5)/('UPS RATES'!E6) -> 0.24008574 | F6: =SUM('UPS RATES'!F6-'FedEx Rates'!F5)/('UPS RATES'!F6) -> 0.24378109 | G6: =SUM('UPS RATES'!G6-'FedEx Rates'!G5)/('UPS RATES'!G6) -> 0.24306077 | H6: =SUM('UPS RATES'!H6-'FedEx Rates'!H5)/('UPS RATES'!H6) -> 0.24277457 | I6: =SUM('UPS RATES'!I6-'FedEx Rates'!I5)/('UPS RATES'!I6) -> 0.28762136 | ... AC6: =SUM('UPS RATES'!AC6-'FedEx Rates'!AC5)/('UPS RATES'!AC6) -> 0.52380952
A7: 5 | B7: =SUM('UPS RATES'!B7-'FedEx Rates'!B6)/('UPS RATES'!B7) -> 0.24193548 | C7: =SUM('UPS RATES'!C7-'FedEx Rates'!C6)/('UPS RATES'!C7) -> 0.24193548 | D7: =SUM('UPS RATES'!D7-'FedEx Rates'!D6)/('UPS RATES'!D7) -> 0.24193548 | E7: =SUM('UPS RATES'!E7-'FedEx Rates'!E6)/('UPS RATES'!E7) -> 0.23887814 | F7: =SUM('UPS RATES'!F7-'FedEx Rates'!F6)/('UPS RATES'!F7) -> 0.24350408 | G7: =SUM('UPS RATES'!G7-'FedEx Rates'!G6)/('UPS RATES'!G7) -> 0.24156545 | H7: =SUM('UPS RATES'!H7-'FedEx Rates'!H6)/('UPS RATES'!H7) -> 0.24124761 | I7: =SUM('UPS RATES'!I7-'FedEx Rates'!I6)/('UPS RATES'!I7) -> 0.28762136 | ... AC7: =SUM('UPS RATES'!AC7-'FedEx Rates'!AC6)/('UPS RATES'!AC7) -> 0.52201524
A8: 6 | B8: =SUM('UPS RATES'!B8-'FedEx Rates'!B7)/('UPS RATES'!B8) -> 0.24193548 | C8: =SUM('UPS RATES'!C8-'FedEx Rates'!C7)/('UPS RATES'!C8) -> 0.24193548 | D8: =SUM('UPS RATES'!D8-'FedEx Rates'!D7)/('UPS RATES'!D8) -> 0.24630542 | E8: =SUM('UPS RATES'!E8-'FedEx Rates'!E7)/('UPS RATES'!E8) -> 0.23826395 | F8: =SUM('UPS RATES'!F8-'FedEx Rates'!F7)/('UPS RATES'!F8) -> 0.24230254 | G8: =SUM('UPS RATES'!G8-'FedEx Rates'!G7)/('UPS RATES'!G8) -> 0.24165149 | H8: =SUM('UPS RATES'!H8-'FedEx Rates'!H7)/('UPS RATES'!H8) -> 0.24127907 | I8: =SUM('UPS RATES'!I8-'FedEx Rates'!I7)/('UPS RATES'!I8) -> 0.28762136 | ... AC8: =SUM('UPS RATES'!AC8-'FedEx Rates'!AC7)/('UPS RATES'!AC8) -> 0.52382685
A9: 7 | B9: =SUM('UPS RATES'!B9-'FedEx Rates'!B8)/('UPS RATES'!B9) -> 0.24193548 | C9: =SUM('UPS RATES'!C9-'FedEx Rates'!C8)/('UPS RATES'!C9) -> 0.24193548 | D9: =SUM('UPS RATES'!D9-'FedEx Rates'!D8)/('UPS RATES'!D9) -> 0.24659091 | E9: =SUM('UPS RATES'!E9-'FedEx Rates'!E8)/('UPS RATES'!E9) -> 0.23824959 | F9: =SUM('UPS RATES'!F9-'FedEx Rates'!F8)/('UPS RATES'!F9) -> 0.24211779 | G9: =SUM('UPS RATES'!G9-'FedEx Rates'!G8)/('UPS RATES'!G9) -> 0.23887974 | H9: =SUM('UPS RATES'!H9-'FedEx Rates'!H8)/('UPS RATES'!H9) -> 0.23955579 | I9: =SUM('UPS RATES'!I9-'FedEx Rates'!I8)/('UPS RATES'!I9) -> 0.28762136 | ... AC9: =SUM('UPS RATES'!AC9-'FedEx Rates'!AC8)/('UPS RATES'!AC9) -> 0.5236636
A10: 8 | B10: =SUM('UPS RATES'!B10-'FedEx Rates'!B9)/('UPS RATES'!B10) -> 0.24193548 | C10: =SUM('UPS RATES'!C10-'FedEx Rates'!C9)/('UPS RATES'!C10) -> 0.24193548 | D10: =SUM('UPS RATES'!D10-'FedEx Rates'!D9)/('UPS RATES'!D10) -> 0.24548353 | E10: =SUM('UPS RATES'!E10-'FedEx Rates'!E9)/('UPS RATES'!E10) -> 0.2384844 | F10: =SUM('UPS RATES'!F10-'FedEx Rates'!F9)/('UPS RATES'!F10) -> 0.24084052 | G10: =SUM('UPS RATES'!G10-'FedEx Rates'!G9)/('UPS RATES'!G10) -> 0.23878365 | H10: =SUM('UPS RATES'!H10-'FedEx Rates'!H9)/('UPS RATES'!H10) -> 0.23967339 | I10: =SUM('UPS RATES'!I10-'FedEx Rates'!I9)/('UPS RATES'!I10) -> 0.28762136 | ... AC10: =SUM('UPS RATES'!AC10-'FedEx Rates'!AC9)/('UPS RATES'!AC10) -> 0.52344782
A11: 9 | B11: =SUM('UPS RATES'!B11-'FedEx Rates'!B10)/('UPS RATES'!B11) -> 0.24193548 | C11: =SUM('UPS RATES'!C11-'FedEx Rates'!C10)/('UPS RATES'!C11) -> 0.23902439 | D11: =SUM('UPS RATES'!D11-'FedEx Rates'!D10)/('UPS RATES'!D11) -> 0.24582104 | E11: =SUM('UPS RATES'!E11-'FedEx Rates'!E10)/('UPS RATES'!E11) -> 0.23875433 | F11: =SUM('UPS RATES'!F11-'FedEx Rates'!F10)/('UPS RATES'!F11) -> 0.23958333 | G11: =SUM('UPS RATES'!G11-'FedEx Rates'!G10)/('UPS RATES'!G11) -> 0.23863636 | H11: =SUM('UPS RATES'!H11-'FedEx Rates'!H10)/('UPS RATES'!H11) -> 0.23882559 | I11: =SUM('UPS RATES'!I11-'FedEx Rates'!I10)/('UPS RATES'!I11) -> 0.28762136 | ... AC11: =SUM('UPS RATES'!AC11-'FedEx Rates'!AC10)/('UPS RATES'!AC11) -> 0.5236998
